Workbook

Sheet Dartmouth WW 2023
A1: J&J | B1: Singles Canoeing | D1: Doubles Canoeing | F1: Portage | H1: Team Pulp Toss | J1: Log Rolling | L1: Scoot Load | N1: Packboard Relay | P1: Axe Throw | R1: Single Buck | T1: Birling | V1: Chain Throw | X1: Disc Stack | Z1: Pole Climb | AB1: Vertical Chop | AD1: Crosscut Sawing | AF1: Team Bow Saw | AH1: Horizontal Chop | AJ1: Splitting | AL1: Firebuild
A2: Teams | B2: Time | C2: Score | D2: Time | E2: Score | F2: Time | G2: Score | H2: Time | I2: Score | J2: Time | K2: Score | L2: Time | M2: Score | N2: Time | O2: Score | P2: Mark | Q2: Score | R2: Time | S2: Score | T2: Time | U2: Score | V2: Time | W2: Score | X2: Raw Pts | Y2: Score | Z2: Time | AA2: Score | AB2: Time | AC2: Score | AD2: Time | AE2: Score | AF2: Time | AG2: Score | AH2: Time | AI2: Score | AJ2: Time | AK2: Score | AL2: Time | AM2: Score | AO2: TEAM | AP2: TOTAL | AQ2: RANK | AR2: Rank | AS2: Team | AT2: Score
A3: Colby A | B3: 0.0035590278 | C3: =IF(B3="DNF","DNF",IF(B3>0,B$29/B3*100,"")) -> 100 | D3: 0.0036898148 | E3: =IF(D3="DNF","DNF",IF(D3>0,D$29/D3*100,"")) -> 79.673777 | F3: 0.0030237269 | G3: =IF(F3="DNF","DNF",IF(F3>0,F$29/F3*100,"")) -> 85.420096 | H3: 0.0017747685 | I3: =IF(H3="DNF","DNF",IF(H3>0,H$29/H3*100,"")) -> 87.204904 | J3: 0.0023172454 | K3: =IF(J3="DNF","DNF",IF(J3>0,J$29/J3*100,"")) -> 42.775086 | L3: 0.0034097222 | M3: =IF(L3="DNF","DNF",IF(L3>0,L$29/L3*100,"")) -> 36.591989 | N3: 0.0035324074 | O3: =IF(N3="DNF","DNF",IF(N3>0,N$29/N3*100,"")) -> 95.969856 | P3: 32 | Q3: =IF(P3="DNF","DNF",IF(P3<>"",P3/P$29*100,"")) -> 100 | R3: 0.00025636574 | S3: =IF(R3="DNF","DNF",IF(R3>0,R$29/R3*100,"")) -> 98.058691 | T3: =Birling!B3 -> 2.5 | U3: =Birling!C3 -> 27.777778 | V3: 0.00067708333 | W3: =IF(V3="DNF","DNF",IF(V3>0,V$29/V3*100,"")) -> 88.888889 | X3: 11 | Y3: =IF(X3="DNF","DNF",IF(X3<>"",X3/X$29*100,"")) -> 50 | Z3: 9.9768519e-05 | AA3: =IF(Z3="DNF","DNF",IF(Z3>0,Z$29/Z3*100,"")) -> 100 | AB3: 0.00066458333 | AC3: =IF(AB3="DNF","DNF",IF(AB3>0,AB$29/AB3*100,"")) -> 71.107628 | AD3: 0.00066087963 | AE3: =IF(AD3="DNF","DNF",IF(AD3>0,AD$29/AD3*100,"")) -> 99.474606 | AF3: 0.0011030093 | AG3: =IF(AF3="DNF","DNF",IF(AF3>0,AF$29/AF3*100,"")) -> 81.636936 | AH3: 0.0017824074 | AI3: =IF(AH3="DNF","DNF",IF(AH3>0,AH$29/AH3*100,"")) -> 63.896104 | AJ3: 0.0043171296 | AK3: =IF(AJ3="DNF","DNF",IF(AJ3>0,AJ$29/AJ3*100,"")) -> 75.067024 | AL3: 0.0040740741 | AM3: =IF(AL3="DNF","DNF",IF(AL3>0,AL$29/AL3*100,"")) -> 91.846591 | AO3: =$A3 -> Colby A | AP3: =SUM(C3,E3,G3,I3,K3,M3,O3,Q3,S3,U3,W3,Y3,AA3,AC3,AE3,AG3,AI3,AK3,AM3) -> 1475.39 | AQ3: =RANK(AP3,$AP$3:$AP$24,0) -> 2 | AR3: 1 | AS3: =INDEX($AO$3:AO22,MATCH(AR3,$AQ$3:$AQ$22,0)) -> Paul Smith's J&J1 | AT3: =INDEX($AP$3:$AP$22,MATCH(AS3,$AO$3:$AO$22,0)) -> 1533.4031
A4: Dartmouth A | B4: 0.0060671296 | C4: =IF(B4="DNF","DNF",IF(B4>0,B$29/B4*100,"")) -> 58.660816 | D4: 0.007994213 | E4: =IF(D4="DNF","DNF",IF(D4>0,D$29/D4*100,"")) -> 36.774287 | F4: 0.0041875 | G4: =IF(F4="DNF","DNF",IF(F4>0,F$29/F4*100,"")) -> 61.680486 | H4: 0.002469213 | I4: =IF(H4="DNF","DNF",IF(H4>0,H$29/H4*100,"")) -> 62.679291 | J4: 0.005759375 | K4: =IF(J4="DNF","DNF",IF(J4>0,J$29/J4*100,"")) -> 17.210265 | L4: 0.0033506944 | M4: =IF(L4="DNF","DNF",IF(L4>0,L$29/L4*100,"")) -> 37.236615 | N4: 0.0038564815 | O4: =IF(N4="DNF","DNF",IF(N4>0,N$29/N4*100,"")) -> 87.905162 | P4: 10 | Q4: =IF(P4="DNF","DNF",IF(P4<>"",P4/P$29*100,"")) -> 31.25 | R4: 0.00070833333 | S4: =IF(R4="DNF","DNF",IF(R4>0,R$29/R4*100,"")) -> 35.490196 | T4: =Birling!B4 -> 3.5 | U4: =Birling!C4 -> 38.888889 | V4: 0.00060185185 | W4: =IF(V4="DNF","DNF",IF(V4>0,V$29/V4*100,"")) -> 100 | X4: 10 | Y4: =IF(X4="DNF","DNF",IF(X4<>"",X4/X$29*100,"")) -> 45.454545 | Z4: DNF | AA4: =IF(Z4="DNF","DNF",IF(Z4>0,Z$29/Z4*100,"")) -> DNF | AB4: 0.014889699 | AC4: =IF(AB4="DNF","DNF",IF(AB4>0,AB$29/AB4*100,"")) -> 3.1738012 | AD4: 0.0013946759 | AE4: =IF(AD4="DNF","DNF",IF(AD4>0,AD$29/AD4*100,"")) -> 47.136929 | AF4: 0.0015393519 | AG4: =IF(AF4="DNF","DNF",IF(AF4>0,AF$29/AF4*100,"")) -> 58.496241 | AH4: 0.0037731481 | AI4: =IF(AH4="DNF","DNF",IF(AH4>0,AH$29/AH4*100,"")) -> 30.184049 | AJ4: 0.0062916667 | AK4: =IF(AJ4="DNF","DNF",IF(AJ4>0,AJ$29/AJ4*100,"")) -> 51.508462 | AL4: 0.0037418981 | AM4: =IF(AL4="DNF","DNF",IF(AL4>0,AL$29/AL4*100,"")) -> 100 | AO4: =$A4 -> Dartmouth A | AP4: =SUM(C4,E4,G4,I4,K4,M4,O4,Q4,S4,U4,W4,Y4,AA4,AC4,AE4,AG4,AI4,AK4,AM4) -> 903.73004 | AQ4: =RANK(AP4,$AP$3:$AP$24,0) -> 12 | AR4: 2 | AS4: =INDEX($AO$3:AO23,MATCH(AR4,$AQ$3:$AQ$22,0)) -> Colby A | AT4: =INDEX($AP$3:$AP$22,MATCH(AS4,$AO$3:$AO$22,0)) -> 1475.39
A5: Paul Smith's J&J1 | B5: 0.0045173611 | C5: =IF(B5="DNF","DNF",IF(B5>0,B$29/B5*100,"")) -> 78.78555 | D5: 0.0036770833 | E5: =IF(D5="DNF","DNF",IF(D5>0,D$29/D5*100,"")) -> 79.949638 | F5: 0.0026921296 | G5: =IF(F5="DNF","DNF",IF(F5>0,F$29/F5*100,"")) -> 95.941531 | H5: 0.0015476852 | I5: =IF(H5="DNF","DNF",IF(H5>0,H$29/H5*100,"")) -> 100 | J5: 0.0015659722 | K5: =IF(J5="DNF","DNF",IF(J5>0,J$29/J5*100,"")) -> 63.296378 | L5: 0.001537037 | M5: =IF(L5="DNF","DNF",IF(L5>0,L$29/L5*100,"")) -> 81.174699 | N5: 0.0033900463 | O5: =IF(N5="DNF","DNF",IF(N5>0,N$29/N5*100,"")) -> 100 | P5: 12 | Q5: =IF(P5="DNF","DNF",IF(P5<>"",P5/P$29*100,"")) -> 37.5 | R5: 0.00025138889 | S5: =IF(R5="DNF","DNF",IF(R5>0,R$29/R5*100,"")) -> 100 | T5: =Birling!B5 -> 70 | U5: =Birling!C5 -> 100 | V5: 0.0013634259 | W5: =IF(V5="DNF","DNF",IF(V5>0,V$29/V5*100,"")) -> 44.142615 | X5: 12 | Y5: =IF(X5="DNF","DNF",IF(X5<>"",X5/X$29*100,"")) -> 54.545455 | Z5: 0.00018148148 | AA5: =IF(Z5="DNF","DNF",IF(Z5>0,Z$29/Z5*100,"")) -> 54.97449 | AB5: 0.00064733796 | AC5: =IF(AB5="DNF","DNF",IF(AB5>0,AB$29/AB5*100,"")) -> 73.001967 | AD5: 0.00065740741 | AE5: =IF(AD5="DNF","DNF",IF(AD5>0,AD$29/AD5*100,"")) -> 100 | AF5: 0.00090046296 | AG5: =IF(AF5="DNF","DNF",IF(AF5>0,AF$29/AF5*100,"")) -> 100 | AH5: 0.0013912037 | AI5: =IF(AH5="DNF","DNF",IF(AH5>0,AH$29/AH5*100,"")) -> 81.863561 | AJ5: 0.0036168981 | AK5: =IF(AJ5="DNF","DNF",IF(AJ5>0,AJ$29/AJ5*100,"")) -> 89.6 | AL5: 0.0037939815 | AM5: =IF(AL5="DNF","DNF",IF(AL5>0,AL$29/AL5*100,"")) -> 98.627212 | AO5: =$A5 -> Paul Smith's J&J1 | AP5: =SUM(C5,E5,G5,I5,K5,M5,O5,Q5,S5,U5,W5,Y5,AA5,AC5,AE5,AG5,AI5,AK5,AM5) -> 1533.4031 | AQ5: =RANK(AP5,$AP$3:$AP$24,0) -> 1 | AR5: 3 | AS5: =INDEX($AO$3:AO24,MATCH(AR5,$AQ$3:$AQ$22,0)) -> UConn J&J A | AT5: =INDEX($AP$3:$AP$22,MATCH(AS5,$AO$3:$AO$22,0)) -> 1383.6685
A6: Ranger J&J | B6: 0.0042835648 | C6: =IF(B6="DNF","DNF",IF(B6>0,B$29/B6*100,"")) -> 83.085653 | D6: 0.0029398148 | E6: =IF(D6="DNF","DNF",IF(D6>0,D$29/D6*100,"")) -> 100 | F6: 0.0034421296 | G6: =IF(F6="DNF","DNF",IF(F6>0,F$29/F6*100,"")) -> 75.036987 | H6: 0.0023296296 | I6: =IF(H6="DNF","DNF",IF(H6>0,H$29/H6*100,"")) -> 66.434817 | J6: 0.003616088 | K6: =IF(J6="DNF","DNF",IF(J6>0,J$29/J6*100,"")) -> 27.41094 | L6: 0.0027631944 | M6: =IF(L6="DNF","DNF",IF(L6>0,L$29/L6*100,"")) -> 45.153724 | N6: 0.0034872685 | O6: =IF(N6="DNF","DNF",IF(N6>0,N$29/N6*100,"")) -> 97.212081 | P6: 24 | Q6: =IF(P6="DNF","DNF",IF(P6<>"",P6/P$29*100,"")) -> 75 | R6: 0.00054293981 | S6: =IF(R6="DNF","DNF",IF(R6>0,R$29/R6*100,"")) -> 46.301428 | T6: =Birling!B6 -> 40.5 | U6: =Birling!C6 -> 90 | V6: 0.001568287 | W6: =IF(V6="DNF","DNF",IF(V6>0,V$29/V6*100,"")) -> 38.376384 | X6: 8 | Y6: =IF(X6="DNF","DNF",IF(X6<>"",X6/X$29*100,"")) -> 36.363636 | Z6: 0.00011712963 | AA6: =IF(Z6="DNF","DNF",IF(Z6>0,Z$29/Z6*100,"")) -> 85.177866 | AB6: 0.0017888889 | AC6: =IF(AB6="DNF","DNF",IF(AB6>0,AB$29/AB6*100,"")) -> 26.416925 | AD6: 0.001224537 | AE6: =IF(AD6="DNF","DNF",IF(AD6>0,AD$29/AD6*100,"")) -> 53.6862 | AF6: 0.0013981481 | AG6: =IF(AF6="DNF","DNF",IF(AF6>0,AF$29/AF6*100,"")) -> 64.403974 | AH6: 0.003155787 | AI6: =IF(AH6="DNF","DNF",IF(AH6>0,AH$29/AH6*100,"")) -> 36.088902 | AJ6: 0.0053645833 | AK6: =IF(AJ6="DNF","DNF",IF(AJ6>0,AJ$29/AJ6*100,"")) -> 60.409924 | AL6: 0.0051388889 | AM6: =IF(AL6="DNF","DNF",IF(AL6>0,AL$29/AL6*100,"")) -> 72.815315 | AO6: =$A6 -> Ranger J&J | AP6: =SUM(C6,E6,G6,I6,K6,M6,O6,Q6,S6,U6,W6,Y6,AA6,AC6,AE6,AG6,AI6,AK6,AM6) -> 1179.3748 | AQ6: =RANK(AP6,$AP$3:$AP$24,0) -> 7 | AR6: 4 | AS6: =INDEX($AO$3:AO25,MATCH(AR6,$AQ$3:$AQ$22,0)) -> Paul Smith's J&J2 | AT6: =INDEX($AP$3:$AP$22,MATCH(AS6,$AO$3:$AO$22,0)) -> 1378.8561
A7: UConn J&J A | B7: 0.0045428241 | C7: =IF(B7="DNF","DNF",IF(B7>0,B$29/B7*100,"")) -> 78.343949 | D7: 0.0034108796 | E7: =IF(D7="DNF","DNF",IF(D7>0,D$29/D7*100,"")) -> 86.189345 | F7: 0.0029965278 | G7: =IF(F7="DNF","DNF",IF(F7>0,F$29/F7*100,"")) -> 86.195442 | H7: 0.0020981481 | I7: =IF(H7="DNF","DNF",IF(H7>0,H$29/H7*100,"")) -> 73.764342 | J7: 0.0009912037 | K7: =IF(J7="DNF","DNF",IF(J7>0,J$29/J7*100,"")) -> 100 | L7: 0.0012476852 | M7: =IF(L7="DNF","DNF",IF(L7>0,L$29/L7*100,"")) -> 100 | N7: 0.0036979167 | O7: =IF(N7="DNF","DNF",IF(N7>0,N$29/N7*100,"")) -> 91.674491 | P7: 16 | Q7: =IF(P7="DNF","DNF",IF(P7<>"",P7/P$29*100,"")) -> 50 | R7: 0.00029814815 | S7: =IF(R7="DNF","DNF",IF(R7>0,R$29/R7*100,"")) -> 84.31677 | T7: =Birling!B7 -> 2.5 | U7: =Birling!C7 -> 27.777778 | V7: 0.0020451389 | W7: =IF(V7="DNF","DNF",IF(V7>0,V$29/V7*100,"")) -> 29.42841 | X7: 17 | Y7: =IF(X7="DNF","DNF",IF(X7<>"",X7/X$29*100,"")) -> 77.272727 | Z7: 0.00028854167 | AA7: =IF(Z7="DNF","DNF",IF(Z7>0,Z$29/Z7*100,"")) -> 34.576815 | AB7: 0.00047256944 | AC7: =IF(AB7="DNF","DNF",IF(AB7>0,AB$29/AB7*100,"")) -> 100 | AD7: 0.00092476852 | AE7: =IF(AD7="DNF","DNF",IF(AD7>0,AD$29/AD7*100,"")) -> 71.088861 | AF7: 0.0010590278 | AG7: =IF(AF7="DNF","DNF",IF(AF7>0,AF$29/AF7*100,"")) -> 85.027322 | AH7: 0.0011388889 | AI7: =IF(AH7="DNF","DNF",IF(AH7>0,AH$29/AH7*100,"")) -> 100 | AJ7: 0.0055833333 | AK7: =IF(AJ7="DNF","DNF",IF(AJ7>0,AJ$29/AJ7*100,"")) -> 58.043118 | AL7: 0.0074884259 | AM7: =IF(AL7="DNF","DNF",IF(AL7>0,AL$29/AL7*100,"")) -> 49.969088 | AO7: =$A7 -> UConn J&J A | AP7: =SUM(C7,E7,G7,I7,K7,M7,O7,Q7,S7,U7,W7,Y7,AA7,AC7,AE7,AG7,AI7,AK7,AM7) -> 1383.6685 | AQ7: =RANK(AP7,$AP$3:$AP$24,0) -> 3 | AR7: 5 | AS7: =INDEX($AO$3:AO26,MATCH(AR7,$AQ$3:$AQ$22,0)) -> UNH K | AT7: =INDEX($AP$3:$AP$22,MATCH(AS7,$AO$3:$AO$22,0)) -> 1313.8517
A8: UNH J | B8: 0.0047800926 | C8: =IF(B8="DNF","DNF",IF(B8>0,B$29/B8*100,"")) -> 74.455206 | D8: 0.0041805556 | E8: =IF(D8="DNF","DNF",IF(D8>0,D$29/D8*100,"")) -> 70.321152 | F8: 0.0030381944 | G8: =IF(F8="DNF","DNF",IF(F8>0,F$29/F8*100,"")) -> 85.013333 | H8: 0.0019233796 | I8: =IF(H8="DNF","DNF",IF(H8>0,H$29/H8*100,"")) -> 80.466964 | J8: 0.0032417245 | K8: =IF(J8="DNF","DNF",IF(J8>0,J$29/J8*100,"")) -> 30.576432 | L8: 0.0033784722 | M8: =IF(L8="DNF","DNF",IF(L8>0,L$29/L8*100,"")) -> 36.930456 | N8: 0.0045034722 | O8: =IF(N8="DNF","DNF",IF(N8>0,N$29/N8*100,"")) -> 75.276279 | P8: 22 | Q8: =IF(P8="DNF","DNF",IF(P8<>"",P8/P$29*100,"")) -> 68.75 | R8: 0.00027395833 | S8: =IF(R8="DNF","DNF",IF(R8>0,R$29/R8*100,"")) -> 91.761724 | T8: =Birling!B8 -> 3.1 | U8: =Birling!C8 -> 34.444444 | V8: 0.0024884259 | W8: =IF(V8="DNF","DNF",IF(V8>0,V$29/V8*100,"")) -> 24.186047 | X8: 14 | Y8: =IF(X8="DNF","DNF",IF(X8<>"",X8/X$29*100,"")) -> 63.636364 | Z8: 0.00016921296 | AA8: =IF(Z8="DNF","DNF",IF(Z8>0,Z$29/Z8*100,"")) -> 58.960328 | AB8: 0.0012604167 | AC8: =IF(AB8="DNF","DNF",IF(AB8>0,AB$29/AB8*100,"")) -> 37.493113 | AD8: 0.00084490741 | AE8: =IF(AD8="DNF","DNF",IF(AD8>0,AD$29/AD8*100,"")) -> 77.808219 | AF8: 0.001412037 | AG8: =IF(AF8="DNF","DNF",IF(AF8>0,AF$29/AF8*100,"")) -> 63.770492 | AH8: 0.0022916667 | AI8: =IF(AH8="DNF","DNF",IF(AH8>0,AH$29/AH8*100,"")) -> 49.69697 | AJ8: 0.0074131944 | AK8: =IF(AJ8="DNF","DNF",IF(AJ8>0,AJ$29/AJ8*100,"")) -> 43.715847 | AL8: 0.0053298611 | AM8: =IF(AL8="DNF","DNF",IF(AL8>0,AL$29/AL8*100,"")) -> 70.206298 | AO8: =$A8 -> UNH J | AP8: =SUM(C8,E8,G8,I8,K8,M8,O8,Q8,S8,U8,W8,Y8,AA8,AC8,AE8,AG8,AI8,AK8,AM8) -> 1137.4697 | AQ8: =RANK(AP8,$AP$3:$AP$24,0) -> 8 | AR8: 6 | AS8: =INDEX($AO$3:AO27,MATCH(AR8,$AQ$3:$AQ$22,0)) -> Colby B | AT8: =INDEX($AP$3:$AP$22,MATCH(AS8,$AO$3:$AO$22,0)) -> 1251.2942
A9: UVM | B9: 0.0059270833 | C9: =IF(B9="DNF","DNF",IF(B9>0,B$29/B9*100,"")) -> 60.046866 | D9: 0.0044606481 | E9: =IF(D9="DNF","DNF",IF(D9>0,D$29/D9*100,"")) -> 65.905553 | F9: 0.0045092593 | G9: =IF(F9="DNF","DNF",IF(F9>0,F$29/F9*100,"")) -> 57.279261 | H9: 0.0022053241 | I9: =IF(H9="DNF","DNF",IF(H9>0,H$29/H9*100,"")) -> 70.17949 | J9: 0.0022085648 | K9: =IF(J9="DNF","DNF",IF(J9>0,J$29/J9*100,"")) -> 44.879992 | L9: 0.0017496528 | M9: =IF(L9="DNF","DNF",IF(L9>0,L$29/L9*100,"")) -> 71.310445 | N9: 0.0042349537 | O9: =IF(N9="DNF","DNF",IF(N9>0,N$29/N9*100,"")) -> 80.049194 | P9: 16 | Q9: =IF(P9="DNF","DNF",IF(P9<>"",P9/P$29*100,"")) -> 50 | R9: 0.00065590278 | S9: =IF(R9="DNF","DNF",IF(R9>0,R$29/R9*100,"")) -> 38.327157 | T9: =Birling!B9 -> 7.2 | U9: =Birling!C9 -> 80 | V9: 0.0016423611 | W9: =IF(V9="DNF","DNF",IF(V9>0,V$29/V9*100,"")) -> 36.645525 | X9: 9 | Y9: =IF(X9="DNF","DNF",IF(X9<>"",X9/X$29*100,"")) -> 40.909091 | Z9: 0.0003 | AA9: =IF(Z9="DNF","DNF",IF(Z9>0,Z$29/Z9*100,"")) -> 33.256173 | AB9: 0.0061207176 | AC9: =IF(AB9="DNF","DNF",IF(AB9>0,AB$29/AB9*100,"")) -> 7.7208177 | AD9: 0.00097685185 | AE9: =IF(AD9="DNF","DNF",IF(AD9>0,AD$29/AD9*100,"")) -> 67.298578 | AF9: 0.0015555556 | AG9: =IF(AF9="DNF","DNF",IF(AF9>0,AF$29/AF9*100,"")) -> 57.886905 | AH9: 0.0067928241 | AI9: =IF(AH9="DNF","DNF",IF(AH9>0,AH$29/AH9*100,"")) -> 16.766059 | AJ9: 0.0050027778 | AK9: =IF(AJ9="DNF","DNF",IF(AJ9>0,AJ$29/AJ9*100,"")) -> 64.778827 | AL9: 0.0062384259 | AM9: =IF(AL9="DNF","DNF",IF(AL9>0,AL$29/AL9*100,"")) -> 59.981447 | AO9: =$A9 -> UVM | AP9: =SUM(C9,E9,G9,I9,K9,M9,O9,Q9,S9,U9,W9,Y9,AA9,AC9,AE9,AG9,AI9,AK9,AM9) -> 1003.2214 | AQ9: =RANK(AP9,$AP$3:$AP$24,0) -> 10 | AR9: 7 | AS9: =INDEX($AO$3:AO28,MATCH(AR9,$AQ$3:$AQ$22,0)) -> Ranger J&J | AT9: =INDEX($AP$3:$AP$22,MATCH(AS9,$AO$3:$AO$22,0)) -> 1179.3748
A10: Colby B | B10: 0.0043738426 | C10: =IF(B10="DNF","DNF",IF(B10>0,B$29/B10*100,"")) -> 81.370733 | D10: 0.0030949074 | E10: =IF(D10="DNF","DNF",IF(D10>0,D$29/D10*100,"")) -> 94.988781 | F10: 0.002924537 | G10: =IF(F10="DNF","DNF",IF(F10>0,F$29/F10*100,"")) -> 88.317239 | H10: 0.002384838 | I10: =IF(H10="DNF","DNF",IF(H10>0,H$29/H10*100,"")) -> 64.89687 | J10: 0.0040884259 | K10: =IF(J10="DNF","DNF",IF(J10>0,J$29/J10*100,"")) -> 24.24414 | L10: 0.0034641204 | M10: =IF(L10="DNF","DNF",IF(L10>0,L$29/L10*100,"")) -> 36.017374 | N10: 0.0035601852 | O10: =IF(N10="DNF","DNF",IF(N10>0,N$29/N10*100,"")) -> 95.221066 | P10: 25 | Q10: =IF(P10="DNF","DNF",IF(P10<>"",P10/P$29*100,"")) -> 78.125 | R10: 0.00041041667 | S10: =IF(R10="DNF","DNF",IF(R10>0,R$29/R10*100,"")) -> 61.252115 | T10: =Birling!B10 -> 3.1 | U10: =Birling!C10 -> 34.444444 | V10: 0.00067592593 | W10: =IF(V10="DNF","DNF",IF(V10>0,V$29/V10*100,"")) -> 89.041096 | X10: 12 | Y10: =IF(X10="DNF","DNF",IF(X10<>"",X10/X$29*100,"")) -> 54.545455 | Z10: 0.00020856481 | AA10: =IF(Z10="DNF","DNF",IF(Z10>0,Z$29/Z10*100,"")) -> 47.835738 | AB10: 0.0013726852 | AC10: =IF(AB10="DNF","DNF",IF(AB10>0,AB$29/AB10*100,"")) -> 34.426644 | AD10: 0.00079513889 | AE10: =IF(AD10="DNF","DNF",IF(AD10>0,AD$29/AD10*100,"")) -> 82.678311 | AF10: 0.0014502315 | AG10: =IF(AF10="DNF","DNF",IF(AF10>0,AF$29/AF10*100,"")) -> 62.090982 | AH10: 0.0029768519 | AI10: =IF(AH10="DNF","DNF",IF(AH10>0,AH$29/AH10*100,"")) -> 38.258165 | AJ10: 0.0032407407 | AK10: =IF(AJ10="DNF","DNF",IF(AJ10>0,AJ$29/AJ10*100,"")) -> 100 | AL10: 0.0044791667 | AM10: =IF(AL10="DNF","DNF",IF(AL10>0,AL$29/AL10*100,"")) -> 83.540052 | AO10: =$A10 -> Colby B | AP10: =SUM(C10,E10,G10,I10,K10,M10,O10,Q10,S10,U10,W10,Y10,AA10,AC10,AE10,AG10,AI10,AK10,AM10) -> 1251.2942 | AQ10: =RANK(AP10,$AP$3:$AP$24,0) -> 6 | AR10: 8 | AS10: =INDEX($AO$3:AO29,MATCH(AR10,$AQ$3:$AQ$22,0)) -> UNH J | AT10: =INDEX($AP$3:$AP$22,MATCH(AS10,$AO$3:$AO$22,0)) -> 1137.4697
A11: Paul Smith's J&J2 | B11: 0.0047627315 | C11: =IF(B11="DNF","DNF",IF(B11>0,B$29/B11*100,"")) -> 74.72661 | D11: 0.0036030093 | E11: =IF(D11="DNF","DNF",IF(D11>0,D$29/D11*100,"")) -> 81.593318 | F11: 0.0030578704 | G11: =IF(F11="DNF","DNF",IF(F11>0,F$29/F11*100,"")) -> 84.466313 | H11: 0.0016979167 | I11: =IF(H11="DNF","DNF",IF(H11>0,H$29/H11*100,"")) -> 91.152011 | J11: 0.0011252894 | K11: =IF(J11="DNF","DNF",IF(J11>0,J$29/J11*100,"")) -> 88.08434 | L11: 0.0014175926 | M11: =IF(L11="DNF","DNF",IF(L11>0,L$29/L11*100,"")) -> 88.01437 | N11: 0.0038009259 | O11: =IF(N11="DNF","DNF",IF(N11>0,N$29/N11*100,"")) -> 89.190012 | P11: 22 | Q11: =IF(P11="DNF","DNF",IF(P11<>"",P11/P$29*100,"")) -> 68.75 | R11: 0.00046643519 | S11: =IF(R11="DNF","DNF",IF(R11>0,R$29/R11*100,"")) -> 53.895782 | T11: =Birling!B11 -> 2.4 | U11: =Birling!C11 -> 26.666667 | V11: 0.0016898148 | W11: =IF(V11="DNF","DNF",IF(V11>0,V$29/V11*100,"")) -> 35.616438 | X11: 22 | Y11: =IF(X11="DNF","DNF",IF(X11<>"",X11/X$29*100,"")) -> 100 | Z11: 0.00024224537 | AA11: =IF(Z11="DNF","DNF",IF(Z11>0,Z$29/Z11*100,"")) -> 41.184902 | AB11: 0.0011516204 | AC11: =IF(AB11="DNF","DNF",IF(AB11>0,AB$29/AB11*100,"")) -> 41.035176 | AD11: 0.00068055556 | AE11: =IF(AD11="DNF","DNF",IF(AD11>0,AD$29/AD11*100,"")) -> 96.598639 | AF11: 0.00096064815 | AG11: =IF(AF11="DNF","DNF",IF(AF11>0,AF$29/AF11*100,"")) -> 93.73494 | AH11: 0.0023449074 | AI11: =IF(AH11="DNF","DNF",IF(AH11>0,AH$29/AH11*100,"")) -> 48.568608 | AJ11: 0.0037893519 | AK11: =IF(AJ11="DNF","DNF",IF(AJ11>0,AJ$29/AJ11*100,"")) -> 85.522297 | AL11: 0.0041550926 | AM11: =IF(AL11="DNF","DNF",IF(AL11>0,AL$29/AL11*100,"")) -> 90.05571 | AO11: =$A11 -> Paul Smith's J&J2 | AP11: =SUM(C11,E11,G11,I11,K11,M11,O11,Q11,S11,U11,W11,Y11,AA11,AC11,AE11,AG11,AI11,AK11,AM11) -> 1378.8561 | AQ11: =RANK(AP11,$AP$3:$AP$24,0) -> 4 | AR11: 9 | AS11: =INDEX($AO$3:AO30,MATCH(AR11,$AQ$3:$AQ$22,0)) -> UConn J&J B | AT11: =INDEX($AP$3:$AP$22,MATCH(AS11,$AO$3:$AO$22,0)) -> 1012.1348
A12: UConn J&J B | B12: 0.0059143519 | C12: =IF(B12="DNF","DNF",IF(B12>0,B$29/B12*100,"")) -> 60.176125 | D12: 0.007130787 | E12: =IF(D12="DNF","DNF",IF(D12>0,D$29/D12*100,"")) -> 41.227074 | F12: 0.0034490741 | G12: =IF(F12="DNF","DNF",IF(F12>0,F$29/F12*100,"")) -> 74.885906 | H12: 0.0022322917 | I12: =IF(H12="DNF","DNF",IF(H12>0,H$29/H12*100,"")) -> 69.331674 | J12: 0.0023997106 | K12: =IF(J12="DNF","DNF",IF(J12>0,J$29/J12*100,"")) -> 41.305134 | L12: 0.0014699074 | M12: =IF(L12="DNF","DNF",IF(L12>0,L$29/L12*100,"")) -> 84.88189 | N12: 0.0037847222 | O12: =IF(N12="DNF","DNF",IF(N12>0,N$29/N12*100,"")) -> 89.571865 | P12: 0 | Q12: =IF(P12="DNF","DNF",IF(P12<>"",P12/P$29*100,"")) -> 0 | R12: 0.000625 | S12: =IF(R12="DNF","DNF",IF(R12>0,R$29/R12*100,"")) -> 40.222222 | T12: =Birling!B12 -> 3.9 | U12: =Birling!C12 -> 43.333333 | V12: 0.0012465278 | W12: =IF(V12="DNF","DNF",IF(V12>0,V$29/V12*100,"")) -> 48.282266 | X12: 20 | Y12: =IF(X12="DNF","DNF",IF(X12<>"",X12/X$29*100,"")) -> 90.909091 | Z12: 0.00057638889 | AA12: =IF(Z12="DNF","DNF",IF(Z12>0,Z$29/Z12*100,"")) -> 17.309237 | AB12: 0.0012530093 | AC12: =IF(AB12="DNF","DNF",IF(AB12>0,AB$29/AB12*100,"")) -> 37.714761 | AD12: 0.00095833333 | AE12: =IF(AD12="DNF","DNF",IF(AD12>0,AD$29/AD12*100,"")) -> 68.599034 | AF12: 0.0014201389 | AG12: =IF(AF12="DNF","DNF",IF(AF12>0,AF$29/AF12*100,"")) -> 63.406683 | AH12: 0.0020405093 | AI12: =IF(AH12="DNF","DNF",IF(AH12>0,AH$29/AH12*100,"")) -> 55.813953 | AJ12: 0.0064710648 | AK12: =IF(AJ12="DNF","DNF",IF(AJ12>0,AJ$29/AJ12*100,"")) -> 50.080486 | AL12: 0.010665509 | AM12: =IF(AL12="DNF","DNF",IF(AL12>0,AL$29/AL12*100,"")) -> 35.084102 | AO12: =$A12 -> UConn J&J B | AP12: =SUM(C12,E12,G12,I12,K12,M12,O12,Q12,S12,U12,W12,Y12,AA12,AC12,AE12,AG12,AI12,AK12,AM12) -> 1012.1348 | AQ12: =RANK(AP12,$AP$3:$AP$24,0) -> 9 | AR12: 10 | AS12: =INDEX($AO$3:AO31,MATCH(AR12,$AQ$3:$AQ$22,0)) -> UVM | AT12: =INDEX($AP$3:$AP$22,MATCH(AS12,$AO$3:$AO$22,0)) -> 1003.2214
A13: UNH K | B13: 0.0050405093 | C13: =IF(B13="DNF","DNF",IF(B13>0,B$29/B13*100,"")) -> 70.608496 | D13: 0.0033333333 | E13: =IF(D13="DNF","DNF",IF(D13>0,D$29/D13*100,"")) -> 88.194444 | F13: 0.0025828704 | G13: =IF(F13="DNF","DNF",IF(F13>0,F$29/F13*100,"")) -> 100 | H13: 0.0018138889 | I13: =IF(H13="DNF","DNF",IF(H13>0,H$29/H13*100,"")) -> 85.324145 | J13: 0.0015891204 | K13: =IF(J13="DNF","DNF",IF(J13>0,J$29/J13*100,"")) -> 62.374363 | L13: 0.0051851852 | M13: =IF(L13="DNF","DNF",IF(L13>0,L$29/L13*100,"")) -> 24.0625 | N13: 0.0046898148 | O13: =IF(N13="DNF","DNF",IF(N13>0,N$29/N13*100,"")) -> 72.285291 | P13: 23 | Q13: =IF(P13="DNF","DNF",IF(P13<>"",P13/P$29*100,"")) -> 71.875 | R13: 0.00036342593 | S13: =IF(R13="DNF","DNF",IF(R13>0,R$29/R13*100,"")) -> 69.171975 | T13: =Birling!B13 -> 43.1 | U13: =Birling!C13 -> 85 | V13: 0.0014652778 | W13: =IF(V13="DNF","DNF",IF(V13>0,V$29/V13*100,"")) -> 41.07425 | X13: 12 | Y13: =IF(X13="DNF","DNF",IF(X13<>"",X13/X$29*100,"")) -> 54.545455 | Z13: 0.00010983796 | AA13: =IF(Z13="DNF","DNF",IF(Z13>0,Z$29/Z13*100,"")) -> 90.832455 | AB13: 0.00079050926 | AC13: =IF(AB13="DNF","DNF",IF(AB13>0,AB$29/AB13*100,"")) -> 59.780381 | AD13: 0.00086805556 | AE13: =IF(AD13="DNF","DNF",IF(AD13>0,AD$29/AD13*100,"")) -> 75.733333 | AF13: 0.0011284722 | AG13: =IF(AF13="DNF","DNF",IF(AF13>0,AF$29/AF13*100,"")) -> 79.794872 | AH13: 0.0024976852 | AI13: =IF(AH13="DNF","DNF",IF(AH13>0,AH$29/AH13*100,"")) -> 45.597776 | AJ13: 0.0042939815 | AK13: =IF(AJ13="DNF","DNF",IF(AJ13>0,AJ$29/AJ13*100,"")) -> 75.471698 | AL13: 0.0060231481 | AM13: =IF(AL13="DNF","DNF",IF(AL13>0,AL$29/AL13*100,"")) -> 62.125288 | AO13: =$A13 -> UNH K | AP13: =SUM(C13,E13,G13,I13,K13,M13,O13,Q13,S13,U13,W13,Y13,AA13,AC13,AE13,AG13,AI13,AK13,AM13) -> 1313.8517 | AQ13: =RANK(AP13,$AP$3:$AP$24,0) -> 5 | AR13: 11 | AS13: =INDEX($AO$3:AO32,MATCH(AR13,$AQ$3:$AQ$22,0)) -> Colby C | AT13: =INDEX($AP$3:$AP$22,MATCH(AS13,$AO$3:$AO$22,0)) -> 944.37672
A14: Colby C | B14: 0.0044756944 | C14: =IF(B14="DNF","DNF",IF(B14>0,B$29/B14*100,"")) -> 79.519007 | D14: 0.0074826389 | E14: =IF(D14="DNF","DNF",IF(D14>0,D$29/D14*100,"")) -> 39.288476 | F14: 0.0034421296 | G14: =IF(F14="DNF","DNF",IF(F14>0,F$29/F14*100,"")) -> 75.036987 | H14: 0.0029487269 | I14: =IF(H14="DNF","DNF",IF(H14>0,H$29/H14*100,"")) -> 52.486557 | J14: 0.002989294 | K14: =IF(J14="DNF","DNF",IF(J14>0,J$29/J14*100,"")) -> 33.158455 | L14: 0.0021539352 | M14: =IF(L14="DNF","DNF",IF(L14>0,L$29/L14*100,"")) -> 57.925846 | N14: 0.0041122685 | O14: =IF(N14="DNF","DNF",IF(N14>0,N$29/N14*100,"")) -> 82.437377 | P14: 4 | Q14: =IF(P14="DNF","DNF",IF(P14<>"",P14/P$29*100,"")) -> 12.5 | R14: 0.00051145833 | S14: =IF(R14="DNF","DNF",IF(R14>0,R$29/R14*100,"")) -> 49.151392 | T14: =Birling!B14 -> 2.1 | U14: =Birling!C14 -> 23.333333 | V14: 0.0016689815 | W14: =IF(V14="DNF","DNF",IF(V14>0,V$29/V14*100,"")) -> 36.061026 | X14: 11 | Y14: =IF(X14="DNF","DNF",IF(X14<>"",X14/X$29*100,"")) -> 50 | Z14: 0.00052013889 | AA14: =IF(Z14="DNF","DNF",IF(Z14>0,Z$29/Z14*100,"")) -> 19.18113 | AB14: 0.00087326389 | AC14: =IF(AB14="DNF","DNF",IF(AB14>0,AB$29/AB14*100,"")) -> 54.115308 | AD14: 0.0010243056 | AE14: =IF(AD14="DNF","DNF",IF(AD14>0,AD$29/AD14*100,"")) -> 64.180791 | AF14: 0.0016863426 | AG14: =IF(AF14="DNF","DNF",IF(AF14>0,AF$29/AF14*100,"")) -> 53.397392 | AH14: 0.0067592593 | AI14: =IF(AH14="DNF","DNF",IF(AH14>0,AH$29/AH14*100,"")) -> 16.849315 | AJ14: 0.0050694444 | AK14: =IF(AJ14="DNF","DNF",IF(AJ14>0,AJ$29/AJ14*100,"")) -> 63.926941 | AL14: 0.0045729167 | AM14: =IF(AL14="DNF","DNF",IF(AL14>0,AL$29/AL14*100,"")) -> 81.827385 | AO14: =$A14 -> Colby C | AP14: =SUM(C14,E14,G14,I14,K14,M14,O14,Q14,S14,U14,W14,Y14,AA14,AC14,AE14,AG14,AI14,AK14,AM14) -> 944.37672 | AQ14: =RANK(AP14,$AP$3:$AP$24,0) -> 11 | AR14: 12 | AS14: =INDEX($AO$3:AO33,MATCH(AR14,$AQ$3:$AQ$22,0)) -> Dartmouth A | AT14: =INDEX($AP$3:$AP$22,MATCH(AS14,$AO$3:$AO$22,0)) -> 903.73004
C15: =IF(B15="DNF","DNF",IF(B15>0,B$29/B15*100,"")) | E15: =IF(D15="DNF","DNF",IF(D15>0,D$29/D15*100,"")) | G15: =IF(F15="DNF","DNF",IF(F15>0,F$29/F15*100,"")) | I15: =IF(H15="DNF","DNF",IF(H15>0,H$29/H15*100,"")) | K15: =IF(J15="DNF","DNF",IF(J15>0,J$29/J15*100,"")) | M15: =IF(L15="DNF","DNF",IF(L15>0,L$29/L15*100,"")) | O15: =IF(N15="DNF","DNF",IF(N15>0,N$29/N15*100,"")) | Q15: =IF(P15="DNF","DNF",IF(P15<>"",P15/P$29*100,"")) | S15: =IF(R15="DNF","DNF",IF(R15>0,R$29/R15*100,"")) | W15: =IF(V15="DNF","DNF",IF(V15>0,V$29/V15*100,"")) | Y15: =IF(X15="DNF","DNF",IF(X15<>"",X15/X$29*100,"")) | AA15: =IF(Z15="DNF","DNF",IF(Z15>0,Z$29/Z15*100,"")) | AC15: =IF(AB15="DNF","DNF",IF(AB15>0,AB$29/AB15*100,"")) | AE15: =IF(AD15="DNF","DNF",IF(AD15>0,AD$29/AD15*100,"")) | AG15: =IF(AF15="DNF","DNF",IF(AF15>0,AF$29/AF15*100,"")) | AI15: =IF(AH15="DNF","DNF",IF(AH15>0,AH$29/AH15*100,"")) | AK15: =IF(AJ15="DNF","DNF",IF(AJ15>0,AJ$29/AJ15*100,"")) | AM15: =IF(AL15="DNF","DNF",IF(AL15>0,AL$29/AL15*100,""))
C16: =IF(B16="DNF","DNF",IF(B16>0,B$29/B16*100,"")) | E16: =IF(D16="DNF","DNF",IF(D16>0,D$29/D16*100,"")) | G16: =IF(F16="DNF","DNF",IF(F16>0,F$29/F16*100,"")) | I16: =IF(H16="DNF","DNF",IF(H16>0,H$29/H16*100,"")) | K16: =IF(J16="DNF","DNF",IF(J16>0,J$29/J16*100,"")) | M16: =IF(L16="DNF","DNF",IF(L16>0,L$29/L16*100,"")) | O16: =IF(N16="DNF","DNF",IF(N16>0,N$29/N16*100,"")) | Q16: =IF(P16="DNF","DNF",IF(P16<>"",P16/P$29*100,"")) | S16: =IF(R16="DNF","DNF",IF(R16>0,R$29/R16*100,"")) | W16: =IF(V16="DNF","DNF",IF(V16>0,V$29/V16*100,"")) | Y16: =IF(X16="DNF","DNF",IF(X16<>"",X16/X$29*100,"")) | AA16: =IF(Z16="DNF","DNF",IF(Z16>0,Z$29/Z16*100,"")) | AC16: =IF(AB16="DNF","DNF",IF(AB16>0,AB$29/AB16*100,"")) | AE16: =IF(AD16="DNF","DNF",IF(AD16>0,AD$29/AD16*100,"")) | AG16: =IF(AF16="DNF","DNF",IF(AF16>0,AF$29/AF16*100,"")) | AI16: =IF(AH16="DNF","DNF",IF(AH16>0,AH$29/AH16*100,"")) | AK16: =IF(AJ16="DNF","DNF",IF(AJ16>0,AJ$29/AJ16*100,"")) | AM16: =IF(AL16="DNF","DNF",IF(AL16>0,AL$29/AL16*100,""))
C17: =IF(B17="DNF","DNF",IF(B17>0,B$29/B17*100,"")) | E17: =IF(D17="DNF","DNF",IF(D17>0,D$29/D17*100,"")) | G17: =IF(F17="DNF","DNF",IF(F17>0,F$29/F17*100,"")) | I17: =IF(H17="DNF","DNF",IF(H17>0,H$29/H17*100,"")) | K17: =IF(J17="DNF","DNF",IF(J17>0,J$29/J17*100,"")) | M17: =IF(L17="DNF","DNF",IF(L17>0,L$29/L17*100,"")) | O17: =IF(N17="DNF","DNF",IF(N17>0,N$29/N17*100,"")) | Q17: =IF(P17="DNF","DNF",IF(P17<>"",P17/P$29*100,"")) | S17: =IF(R17="DNF","DNF",IF(R17>0,R$29/R17*100,"")) | W17: =IF(V17="DNF","DNF",IF(V17>0,V$29/V17*100,"")) | Y17: =IF(X17="DNF","DNF",IF(X17<>"",X17/X$29*100,"")) | AA17: =IF(Z17="DNF","DNF",IF(Z17>0,Z$29/Z17*100,"")) | AC17: =IF(AB17="DNF","DNF",IF(AB17>0,AB$29/AB17*100,"")) | AE17: =IF(AD17="DNF","DNF",IF(AD17>0,AD$29/AD17*100,"")) | AG17: =IF(AF17="DNF","DNF",IF(AF17>0,AF$29/AF17*100,"")) | AI17: =IF(AH17="DNF","DNF",IF(AH17>0,AH$29/AH17*100,"")) | AK17: =IF(AJ17="DNF","DNF",IF(AJ17>0,AJ$29/AJ17*100,"")) | AM17: =IF(AL17="DNF","DNF",IF(AL17>0,AL$29/AL17*100,""))
C18: =IF(B18="DNF","DNF",IF(B18>0,B$29/B18*100,"")) | E18: =IF(D18="DNF","DNF",IF(D18>0,D$29/D18*100,"")) | G18: =IF(F18="DNF","DNF",IF(F18>0,F$29/F18*100,"")) | I18: =IF(H18="DNF","DNF",IF(H18>0,H$29/H18*100,"")) | K18: =IF(J18="DNF","DNF",IF(J18>0,J$24/J18*100,"")) | M18: =IF(L18="DNF","DNF",IF(L18>0,L$24/L18*100,"")) | O18: =IF(N18="DNF","DNF",IF(N18>0,N$29/N18*100,"")) | Q18: =IF(P18="DNF","DNF",IF(P18<>"",P18/P$29*100,"")) | S18: =IF(R18="DNF","DNF",IF(R18>0,R$24/R18*100,"")) | W18: =IF(V18="DNF","DNF",IF(V18>0,V$29/V18*100,"")) | Y18: =IF(X18="DNF","DNF",IF(X18<>"",X18/X$29*100,"")) | AA18: =IF(Z18="DNF","DNF",IF(Z18>0,Z$29/Z18*100,"")) | AC18: =IF(AB18="DNF","DNF",IF(AB18>0,AB$29/AB18*100,"")) | AE18: =IF(AD18="DNF","DNF",IF(AD18>0,AD$29/AD18*100,"")) | AG18: =IF(AF18="DNF","DNF",IF(AF18>0,AF$29/AF18*100,"")) | AI18: =IF(AH18="DNF","DNF",IF(AH18>0,AH$29/AH18*100,"")) | AK18: =IF(AJ18="DNF","DNF",IF(AJ18>0,AJ$29/AJ18*100,"")) | AM18: =IF(AL18="DNF","DNF",IF(AL18>0,AL$29/AL18*100,""))
C20: =IF(B20="DNF","DNF",IF(B20>0,B$29/B20*100,"")) | E20: =IF(D20="DNF","DNF",IF(D20>0,D$29/D20*100,"")) | G20: =IF(F20="DNF","DNF",IF(F20>0,F$29/F20*100,"")) | I20: =IF(H20="DNF","DNF",IF(H20>0,H$29/H20*100,"")) | K20: =IF(J20="DNF","DNF",IF(J20>0,J$24/J20*100,"")) | M20: =IF(L20="DNF","DNF",IF(L20>0,L$24/L20*100,"")) | O20: =IF(N20="DNF","DNF",IF(N20>0,N$29/N20*100,"")) | Q20: =IF(P20="DNF","DNF",IF(P20<>"",P20/P$29*100,"")) | S20: =IF(R20="DNF","DNF",IF(R20>0,R$24/R20*100,"")) | W20: =IF(V20="DNF","DNF",IF(V20>0,V$29/V20*100,"")) | Y20: =IF(X20="DNF","DNF",IF(X20<>"",X20/X$29*100,"")) | AA20: =IF(Z20="DNF","DNF",IF(Z20>0,Z$29/Z20*100,"")) | AC20: =IF(AB20="DNF","DNF",IF(AB20>0,AB$29/AB20*100,"")) | AE20: =IF(AD20="DNF","DNF",IF(AD20>0,AD$29/AD20*100,"")) | AG20: =IF(AF20="DNF","DNF",IF(AF20>0,AF$29/AF20*100,"")) | AI20: =IF(AH20="DNF","DNF",IF(AH20>0,AH$29/AH20*100,"")) | AK20: =IF(AJ20="DNF","DNF",IF(AJ20>0,AJ$29/AJ20*100,"")) | AM20: =IF(AL20="DNF","DNF",IF(AL20>0,AL$29/AL20*100,""))
C21: =IF(B21="DNF","DNF",IF(B21>0,B$29/B21*100,"")) | E21: =IF(D21="DNF","DNF",IF(D21>0,D$29/D21*100,"")) | G21: =IF(F21="DNF","DNF",IF(F21>0,F$29/F21*100,"")) | I21: =IF(H21="DNF","DNF",IF(H21>0,H$29/H21*100,"")) | K21: =IF(J21="DNF","DNF",IF(J21>0,J$24/J21*100,"")) | M21: =IF(L21="DNF","DNF",IF(L21>0,L$24/L21*100,"")) | O21: =IF(N21="DNF","DNF",IF(N21>0,N$29/N21*100,"")) | Q21: =IF(P21="DNF","DNF",IF(P21<>"",P21/P$29*100,"")) | S21: =IF(R21="DNF","DNF",IF(R21>0,R$24/R21*100,"")) | W21: =IF(V21="DNF","DNF",IF(V21>0,V$29/V21*100,"")) | Y21: =IF(X21="DNF","DNF",IF(X21<>"",X21/X$29*100,"")) | AA21: =IF(Z21="DNF","DNF",IF(Z21>0,Z$29/Z21*100,"")) | AC21: =IF(AB21="DNF","DNF",IF(AB21>0,AB$29/AB21*100,"")) | AE21: =IF(AD21="DNF","DNF",IF(AD21>0,AD$29/AD21*100,"")) | AG21: =IF(AF21="DNF","DNF",IF(AF21>0,AF$29/AF21*100,"")) | AI21: =IF(AH21="DNF","DNF",IF(AH21>0,AH$29/AH21*100,"")) | AK21: =IF(AJ21="DNF","DNF",IF(AJ21>0,AJ$29/AJ21*100,"")) | AM21: =IF(AL21="DNF","DNF",IF(AL21>0,AL$29/AL21*100,""))
C22: =IF(B22="DNF","DNF",IF(B22>0,B$29/B22*100,"")) | E22: =IF(D22="DNF","DNF",IF(D22>0,D$29/D22*100,"")) | G22: =IF(F22="DNF","DNF",IF(F22>0,F$29/F22*100,"")) | I22: =IF(H22="DNF","DNF",IF(H22>0,H$29/H22*100,"")) | K22: =IF(J22="DNF","DNF",IF(J22>0,J$24/J22*100,"")) | M22: =IF(L22="DNF","DNF",IF(L22>0,L$24/L22*100,"")) | O22: =IF(N22="DNF","DNF",IF(N22>0,N$29/N22*100,"")) | Q22: =IF(P22="DNF","DNF",IF(P22<>"",P22/P$29*100,"")) | S22: =IF(R22="DNF","DNF",IF(R22>0,R$24/R22*100,"")) | W22: =IF(V22="DNF","DNF",IF(V22>0,V$29/V22*100,"")) | Y22: =IF(X22="DNF","DNF",IF(X22<>"",X22/X$29*100,"")) | AA22: =IF(Z22="DNF","DNF",IF(Z22>0,Z$29/Z22*100,"")) | AC22: =IF(AB22="DNF","DNF",IF(AB22>0,AB$29/AB22*100,"")) | AE22: =IF(AD22="DNF","DNF",IF(AD22>0,AD$29/AD22*100,"")) | AG22: =IF(AF22="DNF","DNF",IF(AF22>0,AF$29/AF22*100,"")) | AI22: =IF(AH22="DNF","DNF",IF(AH22>0,AH$29/AH22*100,"")) | AK22: =IF(AJ22="DNF","DNF",IF(AJ22>0,AJ$29/AJ22*100,"")) | AM22: =IF(AL22="DNF","DNF",IF(AL22>0,AL$29/AL22*100,""))
C24: =IF(B24="DNF","DNF",IF(B24>0,B$29/B24*100,"")) | E24: =IF(D24="DNF","DNF",IF(D24>0,D$29/D24*100,"")) | G24: =IF(F24="DNF","DNF",IF(F24>0,F$29/F24*100,"")) | I24: =IF(H24="DNF","DNF",IF(H24>0,H$29/H24*100,"")) | K24: =IF(J24="DNF","DNF",IF(J24>0,J$29/J24*100,"")) | O24: =IF(N24="DNF","DNF",IF(N24>0,N$29/N24*100,"")) | Q24: =IF(P24="DNF","DNF",IF(P24<>"",P24/P$29*100,"")) | S24: =IF(R24="DNF","DNF",IF(R24>0,R$29/R24*100,"")) | W24: =IF(V24="DNF","DNF",IF(V24>0,V$29/V24*100,"")) | Y24: =IF(X24="DNF","DNF",IF(X24<>"",X24/X$29*100,"")) | AA24: =IF(Z24="DNF","DNF",IF(Z24>0,Z$29/Z24*100,"")) | AC24: =IF(AB24="DNF","DNF",IF(AB24>0,AB$29/AB24*100,"")) | AE24: =IF(AD24="DNF","DNF",IF(AD24>0,AD$29/AD24*100,"")) | AG24: =IF(AF24="DNF","DNF",IF(AF24>0,AF$29/AF24*100,"")) | AI24: =IF(AH24="DNF","DNF",IF(AH24>0,AH$29/AH24*100,"")) | AK24: =IF(AJ24="DNF","DNF",IF(AJ24>0,AJ$29/AJ24*100,"")) | AM24: =IF(AL24="DNF","DNF",IF(AL24>0,AL$29/AL24*100,""))
A25: Dartmouth Alum A | B25: 0.0034305556 | C25: =IF(B25="DNF","DNF",IF(B25>0,B$29/B25*100,"")) -> 103.74494 | D25: 0.0028958333 | E25: =IF(D25="DNF","DNF",IF(D25>0,D$29/D25*100,"")) -> 101.51878 | F25: 0.0032944444 | G25: =IF(F25="DNF","DNF",IF(F25>0,F$29/F25*100,"")) -> 78.400787 | H25: 0.0015386574 | I25: =IF(H25="DNF","DNF",IF(H25>0,H$29/H25*100,"")) -> 100.58673 | J25: 0.0030859954 | K25: =IF(J25="DNF","DNF",IF(J25>0,J$29/J25*100,"")) -> 32.119416 | L25: 0.00098935185 | M25: =IF(L25="DNF","DNF",IF(L25>0,L$29/L25*100,"")) -> 126.11137 | N25: 0.0035960648 | O25: =IF(N25="DNF","DNF",IF(N25>0,N$29/N25*100,"")) -> 94.271001 | P25: 28 | Q25: =IF(P25="DNF","DNF",IF(P25<>"",P25/P$29*100,"")) -> 87.5 | R25: 0.00029166667 | S25: =IF(R25="DNF","DNF",IF(R25>0,R$29/R25*100,"")) -> 86.190476 | T25: =Birling!B19 -> 1.4 | U25: =Birling!C19 -> 15.555556 | V25: 0.00070625 | W25: =IF(V25="DNF","DNF",IF(V25>0,V$29/V25*100,"")) -> 85.217961 | X25: 11 | Y25: =IF(X25="DNF","DNF",IF(X25<>"",X25/X$29*100,"")) -> 50 | Z25: 0.00033472222 | AA25: =IF(Z25="DNF","DNF",IF(Z25>0,Z$29/Z25*100,"")) -> 29.806362 | AB25: 0.0008912037 | AC25: =IF(AB25="DNF","DNF",IF(AB25>0,AB$29/AB25*100,"")) -> 53.025974 | AD25: 0.00095833333 | AE25: =IF(AD25="DNF","DNF",IF(AD25>0,AD$29/AD25*100,"")) -> 68.599034 | AF25: 0.0011539352 | AG25: =IF(AF25="DNF","DNF",IF(AF25>0,AF$29/AF25*100,"")) -> 78.034102 | AH25: 0.001099537 | AI25: =IF(AH25="DNF","DNF",IF(AH25>0,AH$29/AH25*100,"")) -> 103.57895 | AJ25: 0.0026851852 | AK25: =IF(AJ25="DNF","DNF",IF(AJ25>0,AJ$29/AJ25*100,"")) -> 120.68966 | AL25: 0.0041736111 | AM25: =IF(AL25="DNF","DNF",IF(AL25>0,AL$29/AL25*100,"")) -> 89.656129 | AO25: =A25 -> Dartmouth Alum A | AP25: =SUM(C25,E25,G25,I25,K25,M25,O25,Q25,S25,U25,W25,Y25,AA25,AC25,AE25,AG25,AI25,AK25,AM25) -> 1504.6072 | AQ25: =RANK(AP25,$AP$25:$AP$28,0) -> 1 | AR25: 1 | AS25: =INDEX($AO$25:AO27,MATCH(AR3,$AQ$25:$AQ$27,0)) -> Dartmouth Alum A | AT25: =INDEX($AP$25:$AP$27,MATCH(AS25,$AO$25:$AO$27,0)) -> 1504.6072
A26: Colby Alum | B26: 0.0057523148 | C26: =IF(B26="DNF","DNF",IF(B26>0,B$29/B26*100,"")) -> 61.871227 | D26: 0.0039131944 | E26: =IF(D26="DNF","DNF",IF(D26>0,D$29/D26*100,"")) -> 75.125702 | F26: 0.0030770833 | G26: =IF(F26="DNF","DNF",IF(F26>0,F$29/F26*100,"")) -> 83.938915 | H26: 0.0022453704 | I26: =IF(H26="DNF","DNF",IF(H26>0,H$29/H26*100,"")) -> 68.927835 | J26: 0.002600463 | K26: =IF(J26="DNF","DNF",IF(J26>0,J$29/J26*100,"")) -> 38.116432 | L26: 0.0011267361 | M26: =IF(L26="DNF","DNF",IF(L26>0,L$29/L26*100,"")) -> 110.73446 | O26: =IF(N26="DNF","DNF",IF(N26>0,N$29/N26*100,"")) | P26: 16 | Q26: =IF(P26="DNF","DNF",IF(P26<>"",P26/P$29*100,"")) -> 50 | R26: 0.00027268519 | S26: =IF(R26="DNF","DNF",IF(R26>0,R$29/R26*100,"")) -> 92.190153 | T26: =Birling!B20 -> 0 | U26: =Birling!C20 -> 0 | V26: 0.00054282407 | W26: =IF(V26="DNF","DNF",IF(V26>0,V$29/V26*100,"")) -> 110.8742 | X26: 11 | Y26: =IF(X26="DNF","DNF",IF(X26<>"",X26/X$29*100,"")) -> 50 | Z26: 0.00016122685 | AA26: =IF(Z26="DNF","DNF",IF(Z26>0,Z$29/Z26*100,"")) -> 61.880833 | AB26: 0.0012893519 | AC26: =IF(AB26="DNF","DNF",IF(AB26>0,AB$29/AB26*100,"")) -> 36.651706 | AD26: 0.00068287037 | AE26: =IF(AD26="DNF","DNF",IF(AD26>0,AD$29/AD26*100,"")) -> 96.271186 | AF26: 0.0012152778 | AG26: =IF(AF26="DNF","DNF",IF(AF26>0,AF$29/AF26*100,"")) -> 74.095238 | AH26: 0.0016898148 | AI26: =IF(AH26="DNF","DNF",IF(AH26>0,AH$29/AH26*100,"")) -> 67.39726 | AJ26: 0.0044907407 | AK26: =IF(AJ26="DNF","DNF",IF(AJ26>0,AJ$29/AJ26*100,"")) -> 72.164948 | AL26: 0.003630787 | AM26: =IF(AL26="DNF","DNF",IF(AL26>0,AL$29/AL26*100,"")) -> 103.06025 | AO26: =A26 -> Colby Alum | AP26: =SUM(C26,E26,G26,I26,K26,M26,O26,Q26,S26,U26,W26,Y26,AA26,AC26,AE26,AG26,AI26,AK26,AM26) -> 1253.3003 | AQ26: =RANK(AP26,$AP$25:$AP$28,0) -> 2 | AR26: 2 | AS26: =INDEX($AO$25:AO28,MATCH(AR4,$AQ$25:$AQ$27,0)) -> Colby Alum | AT26: =INDEX($AP$25:$AP$27,MATCH(AS26,$AO$25:$AO$27,0)) -> 1253.3003
A27: Dartmouth Alum B | B27: 0.00421875 | C27: =IF(B27="DNF","DNF",IF(B27>0,B$29/B27*100,"")) -> 84.36214 | D27: 0.0036354167 | E27: =IF(D27="DNF","DNF",IF(D27>0,D$29/D27*100,"")) -> 80.865966 | F27: 0.0038958333 | G27: =IF(F27="DNF","DNF",IF(F27>0,F$29/F27*100,"")) -> 66.298277 | H27: 0.0026792824 | I27: =IF(H27="DNF","DNF",IF(H27>0,H$29/H27*100,"")) -> 57.764914 | K27: =IF(J27="DNF","DNF",IF(J27>0,J$29/J27*100,"")) | L27: 0.0015020833 | M27: =IF(L27="DNF","DNF",IF(L27>0,L$29/L27*100,"")) -> 83.063646 | N27: 0.0046327546 | O27: =IF(N27="DNF","DNF",IF(N27>0,N$29/N27*100,"")) -> 73.175606 | P27: 24 | Q27: =IF(P27="DNF","DNF",IF(P27<>"",P27/P$29*100,"")) -> 75 | R27: 0.00033101852 | S27: =IF(R27="DNF","DNF",IF(R27>0,R$29/R27*100,"")) -> 75.944056 | T27: =Birling!B21 -> 1.7 | U27: =Birling!C21 -> 18.888889 | V27: 0.00083796296 | W27: =IF(V27="DNF","DNF",IF(V27>0,V$29/V27*100,"")) -> 71.823204 | X27: 7 | Y27: =IF(X27="DNF","DNF",IF(X27<>"",X27/X$29*100,"")) -> 31.818182 | Z27: 0.00031736111 | AA27: =IF(Z27="DNF","DNF",IF(Z27>0,Z$29/Z27*100,"")) -> 31.436907 | AB27: 0.0013818287 | AC27: =IF(AB27="DNF","DNF",IF(AB27>0,AB$29/AB27*100,"")) -> 34.198844 | AD27: 0.0015081019 | AE27: =IF(AD27="DNF","DNF",IF(AD27>0,AD$29/AD27*100,"")) -> 43.591711 | AF27: 0.0015925926 | AG27: =IF(AF27="DNF","DNF",IF(AF27>0,AF$29/AF27*100,"")) -> 56.540698 | AH27: 0.001880787 | AI27: =IF(AH27="DNF","DNF",IF(AH27>0,AH$29/AH27*100,"")) -> 60.553846 | AJ27: 0.0030451389 | AK27: =IF(AJ27="DNF","DNF",IF(AJ27>0,AJ$29/AJ27*100,"")) -> 106.42341 | AL27: 0.0045509259 | AM27: =IF(AL27="DNF","DNF",IF(AL27>0,AL$29/AL27*100,"")) -> 82.222787 | AO27: =A27 -> Dartmouth Alum B | AP27: =SUM(C27,E27,G27,I27,K27,M27,O27,Q27,S27,U27,W27,Y27,AA27,AC27,AE27,AG27,AI27,AK27,AM27) -> 1133.9731 | AQ27: =RANK(AP27,$AP$25:$AP$28,0) -> 3 | AR27: 3 | AS27: =INDEX($AO$25:AO27,MATCH(AR5,$AQ$25:$AQ$27,0)) -> Dartmouth Alum B | AT27: =INDEX($AP$25:$AP$27,MATCH(AS27,$AO$25:$AO$27,0)) -> 1133.9731
C28: =IF(B28="DNF","DNF",IF(B28>0,B$29/B28*100,"")) | E28: =IF(D28="DNF","DNF",IF(D28>0,D$29/D28*100,"")) | G28: =IF(F28="DNF","DNF",IF(F28>0,F$29/F28*100,"")) | I28: =IF(H28="DNF","DNF",IF(H28>0,H$29/H28*100,"")) | K28: =IF(J28="DNF","DNF",IF(J28>0,J$29/J28*100,"")) | M28: =IF(L28="DNF","DNF",IF(L28>0,L$29/L28*100,"")) | O28: =IF(N28="DNF","DNF",IF(N28>0,N$29/N28*100,"")) | Q28: =IF(P28="DNF","DNF",IF(P28<>"",P28/P$29*100,"")) | U28: =IF(T28="DNF","DNF",IF(T28>0,T$29/T28*100,"")) | W28: =IF(V28="DNF","DNF",IF(V28>0,V$29/V28*100,"")) | Y28: =IF(X28="DNF","DNF",IF(X28<>"",X28/X$29*100,"")) | AA28: =IF(Z28="DNF","DNF",IF(Z28>0,Z$29/Z28*100,"")) | AC28: =IF(AB28="DNF","DNF",IF(AB28>0,AB$29/AB28*100,"")) | AE28: =IF(AD28="DNF","DNF",IF(AD28>0,AD$29/AD28*100,"")) | AG28: =IF(AF28="DNF","DNF",IF(AF28>0,AF$29/AF28*100,"")) | AI28: =IF(AH28="DNF","DNF",IF(AH28>0,AH$29/AH28*100,"")) | AM28: =IF(AL28="DNF","DNF",IF(AL28>0,AL$29/AL28*100,""))
A29: Top U-Grad Score | B29: =MIN(B3:B24) -> 0.0035590278 | D29: =MIN(D3:D24) -> 0.0029398148 | F29: =MIN(F3:F24) -> 0.0025828704 | H29: =MIN(H3:H24) -> 0.0015476852 | J29: =MIN(J3:J17) -> 0.0009912037 | L29: =MIN(L3:L17) -> 0.0012476852 | N29: =MIN(N3:N26) -> 0.0033900463 | P29: =MAX(P3:P25) -> 32 | R29: =MIN(R3:R17) -> 0.00025138889 | T29: =MAX(U3:U22) -> 100 | V29: =MIN(V3:V24) -> 0.00060185185 | X29: =MAX(X3:X22) -> 22 | Z29: =MIN(Z3:Z24) -> 9.9768519e-05 | AB29: =MIN(AB3:AB24) -> 0.00047256944 | AD29: =MIN(AD3:AD24) -> 0.00065740741 | AF29: =MIN(AF3:AF24) -> 0.00090046296 | AH29: =MIN(AH3:AH24) -> 0.0011388889 | AJ29: =MIN(AJ3:AJ24) -> 0.0032407407 | AL29: =MIN(AL3:AL24) -> 0.0037418981
A30: 1st Place | B30: {=INDEX($A$3:$A$24, MATCH(B31,B3:B24,0))} -> Colby A | D30: {=INDEX($A$3:$A$24, MATCH(D31,D3:D24,0))} -> Ranger J&J | F30: {=INDEX($A$3:$A$24, MATCH(F31,F3:F24,0))} -> UNH K | H30: {=INDEX($A$3:$A$24, MATCH(H31,H3:H24,0))} -> Paul Smith's J&J1 | J30: {=INDEX($A$3:$A$24, MATCH(J31,J3:J24,0))} -> UConn J&J A | L30: {=INDEX($A$3:$A$24, MATCH(L31,L3:L24,0))} -> UConn J&J A | N30: =INDEX($A$3:$A$24, MATCH(N31,N3:N24,0)) -> Paul Smith's J&J1 | P30: {=INDEX($A$3:$A$24, MATCH(P31,P3:P24,0))} -> Colby A | R30: {=INDEX($A$3:$A$24, MATCH(R31,R3:R24,0))} -> Paul Smith's J&J1 | T30: {=INDEX($A$3:$A$24, MATCH(T31,U3:U24,0))} -> Paul Smith's J&J1 | V30: {=INDEX($A$3:$A$24, MATCH(V31,V3:V24,0))} -> Dartmouth A | X30: {=INDEX($A$3:$A$24, MATCH(X31,X3:X24,0))} -> Paul Smith's J&J2 | Z30: {=INDEX($A$3:$A$24, MATCH(Z31,Z3:Z24,0))} -> Colby A | AB30: {=INDEX($A$3:$A$24, MATCH(AB31,AB3:AB24,0))} -> UConn J&J A | AD30: {=INDEX($A$3:$A$24, MATCH(AD31,AD3:AD24,0))} -> Paul Smith's J&J1 | AF30: {=INDEX($A$3:$A$24, MATCH(AF31,AF3:AF24,0))} -> Paul Smith's J&J1 | AH30: {=INDEX($A$3:$A$24, MATCH(AH31,AH3:AH24,0))} -> UConn J&J A | AJ30: {=INDEX($A$3:$A$24, MATCH(AJ31,AJ3:AJ24,0))} -> Colby B | AL30: =INDEX($A$3:$A$24, MATCH(AL31,AL3:AL24,0)) -> Dartmouth A
A31: Result | B31: =SMALL(B3:B24,1) -> 0.0035590278 | D31: =SMALL(D3:D24,1) -> 0.0029398148 | F31: =SMALL(F3:F24,1) -> 0.0025828704 | H31: =SMALL(H3:H24,1) -> 0.0015476852 | J31: =SMALL(J3:J24,1) -> 0.0009912037 | L31: =SMALL(L3:L24,1) -> 0.0012476852 | N31: =SMALL(N3:N24,1) -> 0.0033900463 | P31: =LARGE(P3:P24,1) -> 32 | R31: =SMALL(R3:R24,1) -> 0.00025138889 | T31: =LARGE(U3:U24,1) -> 100 | V31: =SMALL(V3:V24,1) -> 0.00060185185 | X31: =LARGE(X3:X24,1) -> 22 | Z31: =SMALL(Z3:Z24,1) -> 9.9768519e-05 | AB31: =SMALL(AB3:AB24,1) -> 0.00047256944 | AD31: =SMALL(AD3:AD24,1) -> 0.00065740741 | AF31: =SMALL(AF3:AF24,1) -> 0.00090046296 | AH31: =SMALL(AH3:AH24,1) -> 0.0011388889 | AJ31: =SMALL(AJ3:AJ24,1) -> 0.0032407407 | AL31: =SMALL(AL3:AL24,1) -> 0.0037418981
A32: 2nd Place | B32: {=INDEX($A$3:$A$24, MATCH(B33,B3:B24,0))} -> Ranger J&J | D32: {=INDEX($A$3:$A$24, MATCH(D33,D3:D24,0))} -> Colby B | F32: {=INDEX($A$3:$A$24, MATCH(F33,F3:F24,0))} -> Paul Smith's J&J1 | H32: {=INDEX($A$3:$A$24, MATCH(H33,H3:H24,0))} -> Paul Smith's J&J2 | J32: {=INDEX($A$3:$A$24, MATCH(J33,J3:J24,0))} -> Paul Smith's J&J2 | L32: {=INDEX($A$3:$A$24, MATCH(L33,L3:L24,0))} -> Paul Smith's J&J2 | N32: {=INDEX($A$3:$A$24, MATCH(N33,N3:N24,0))} -> Ranger J&J | P32: UNH | R32: {=INDEX($A$3:$A$24, MATCH(R33,R3:R24,0))} -> Colby A | T32: {=INDEX($A$3:$A$24, MATCH(T33,U3:U24,0))} -> Ranger J&J | V32: {=INDEX($A$3:$A$24, MATCH(V33,V3:V24,0))} -> Colby B | X32: =INDEX( $A$3:$A$24, MATCH(X33,X3:X24,0)) -> UConn J&J B | Z32: {=INDEX($A$3:$A$24, MATCH(Z33,Z3:Z24,0))} -> UNH K | AB32: {=INDEX($A$3:$A$24, MATCH(AB33,AB3:AB24,0))} -> Paul Smith's J&J1 | AD32: {=INDEX($A$3:$A$24, MATCH(AD33,AD3:AD24,0))} -> Colby A | AF32: {=INDEX($A$3:$A$24, MATCH(AF33,AF3:AF24,0))} -> Paul Smith's J&J2 | AH32: {=INDEX($A$3:$A$24, MATCH(AH33,AH3:AH24,0))} -> Paul Smith's J&J1 | AJ32: {=INDEX($A$3:$A$24, MATCH(AJ33,AJ3:AJ24,0))} -> Paul Smith's J&J1 | AL32: =INDEX($A$3:$A$24, MATCH(AL33,AL3:AL24,0)) -> Paul Smith's J&J1
A33: Result | B33: =SMALL(B3:B24,2) -> 0.0042835648 | D33: =SMALL(D3:D24,2) -> 0.0030949074 | F33: =SMALL(F3:F24,2) -> 0.0026921296 | H33: =SMALL(H3:H24,2) -> 0.0016979167 | J33: =SMALL(J3:J24,2) -> 0.0011252894 | L33: =SMALL(L3:L24,2) -> 0.0014175926 | N33: =SMALL(N3:N24,2) -> 0.0034872685 | P33: =LARGE(P3:P24,2) -> 25 | R33: =SMALL(R3:R24,2) -> 0.00025636574 | T33: =LARGE(U3:U24,2) -> 90 | V33: =SMALL(V3:V24,2) -> 0.00067592593 | X33: =LARGE(X3:X24,2) -> 20 | Z33: =SMALL(Z3:Z24,2) -> 0.00010983796 | AB33: =SMALL(AB3:AB24,2) -> 0.00064733796 | AD33: =SMALL(AD3:AD24,2) -> 0.00066087963 | AF33: =SMALL(AF3:AF24,2) -> 0.00096064815 | AH33: =SMALL(AH3:AH24,2) -> 0.0013912037 | AJ33: =SMALL(AJ3:AJ24,2) -> 0.0036168981 | AL33: =SMALL(AL3:AL24,2) -> 0.0037939815
A34: 3rd Place | B34: {=INDEX($A$3:$A$24, MATCH(B35,B3:B24,0))} -> Colby B | D34: {=INDEX($A$3:$A$24, MATCH(D35,D3:D24,0))} -> UNH K | F34: {=INDEX($A$3:$A$24, MATCH(F35,F3:F24,0))} -> Colby B | H34: {=INDEX($A$3:$A$24, MATCH(H35,H3:H24,0))} -> Colby A | J34: {=INDEX($A$3:$A$24, MATCH(J35,J3:J24,0))} -> Paul Smith's J&J1 | L34: {=INDEX($A$3:$A$24, MATCH(L35,L3:L24,0))} -> UConn J&J B | N34: {=INDEX($A$3:$A$24, MATCH(N35,N3:N24,0))} -> Colby A | P34: =INDEX( $A$3:$A$24, MATCH(P35,P3:P24,0)) -> Ranger J&J | R34: {=INDEX($A$3:$A$24, MATCH(R35,R3:R24,0))} -> UNH J | T34: {=INDEX($A$3:$A$24, MATCH(T35,U3:U24,0))} -> UNH K | V34: {=INDEX($A$3:$A$24, MATCH(V35,V3:V24,0))} -> Colby A | X34: =INDEX($A$3:$A$24, MATCH(X35,X3:X24,0)) -> UConn J&J A | Z34: {=INDEX($A$3:$A$24, MATCH(Z35,Z3:Z24,0))} -> Ranger J&J | AB34: {=INDEX($A$3:$A$24, MATCH(AB35,AB3:AB24,0))} -> Colby A | AD34: {=INDEX($A$3:$A$24, MATCH(AD35,AD3:AD24,0))} -> Paul Smith's J&J2 | AF34: {=INDEX($A$3:$A$24, MATCH(AF35,AF3:AF24,0))} -> UConn J&J A | AH34: {=INDEX($A$3:$A$24, MATCH(AH35,AH3:AH24,0))} -> Colby A | AJ34: {=INDEX($A$3:$A$24, MATCH(AJ35,AJ3:AJ24,0))} -> Paul Smith's J&J2 | AL34: =INDEX($A$3:$A$24, MATCH(AL35,AL3:AL24,0)) -> Colby A
A35: Result | B35: =SMALL(B3:B24,3) -> 0.0043738426 | D35: =SMALL(D3:D24,3) -> 0.0033333333 | F35: =SMALL(F3:F24,3) -> 0.002924537 | H35: =SMALL(H3:H24,3) -> 0.0017747685 | J35: =SMALL(J3:J24,3) -> 0.0015659722 | L35: =SMALL(L3:L24,3) -> 0.0014699074 | N35: =SMALL(N3:N24,3) -> 0.0035324074 | P35: =LARGE(P3:P24,3) -> 24 | R35: =SMALL(R3:R24,3) -> 0.00027395833 | T35: =LARGE(U3:U24,3) -> 85 | V35: =SMALL(V3:V24,3) -> 0.00067708333 | X35: =LARGE(X3:X24,3) -> 17 | Z35: =SMALL(Z3:Z24,3) -> 0.00011712963 | AB35: =SMALL(AB3:AB24,3) -> 0.00066458333 | AD35: =SMALL(AD3:AD24,3) -> 0.00068055556 | AF35: =SMALL(AF3:AF24,3) -> 0.0010590278 | AH35: =SMALL(AH3:AH24,3) -> 0.0017824074 | AJ35: =SMALL(AJ3:AJ24,3) -> 0.0037893519 | AL35: =SMALL(AL3:AL24,3) -> 0.0040740741
R36: Dart Alum C: 00:45.04 | AH36: Dart Alum C: 9:45.0 | AJ36: Dart Alum C: 4:49.9 | AL36: Dart Alum C: 7:22.9
AJ37: Dart Alum D: 7:22.0 | AL37: Dart Alum D: 8:42.0
AL38: Dart Alum E: 9:42.0
T59: Scored proportionally - no birl-off
A60: Other Undergrad | B60: Singles Canoeing | D60: Doubles Canoeing | F60: Portage | H60: Team Pulp Toss | J60: Log Rolling | L60: Scoot Load | N60: Packboard Relay | P60: Axe Throw | R60: Single Buck | T60: Birling | V60: Chain Throw | X60: Disc Stack | Z60: Pole Climb | AB60: Vertical Chop | AD60: Crosscut Sawing | AF60: Team Bow Saw | AH60: Horizontal Chop | AJ60: Splitting | AL60: Firebuild
A61: Teams | B61: Time | C61: Score | D61: Time | E61: Score | F61: Time | G61: Score | H61: Time | I61: Score | J61: Time | K61: Score | L61: Time | M61: Score | N61: Time | O61: Score | P61: Mark | Q61: Score | R61: Time | S61: Score | T61: Time | U61: Score | V61: Time | W61: Score | X61: Raw Pts | Y61: Score | Z61: Time | AA61: Score | AB61: Time | AC61: Score | AD61: Time | AE61: Score | AF61: Time | AG61: Score | AH61: Time | AI61: Score | AJ61: Time | AK61: Score | AL61: Time | AM61: Score | AO61: TEAM | AP61: TOTAL | AQ61: RANK | AR61: Rank | AS61: Team | AT61: Score
A62: Dartmouth B | B62: 0.0060428241 | C62: =IF(B62="DNF","DNF",IF(B62>0,B$78/B62*100,"")) -> 58.896763 | D62: 0.0036238426 | E62: =IF(D62="DNF","DNF",IF(D62>0,D$78/D62*100,"")) -> 81.124241 | F62: 0.0037384259 | G62: =IF(F62="DNF","DNF",IF(F62>0,F$78/F62*100,"")) -> 69.089783 | H62: 0.0020493056 | I62: =IF(H62="DNF","DNF",IF(H62>0,H$78/H62*100,"")) -> 75.522422 | J62: 0.0037054398 | K62: =IF(J62="DNF","DNF",IF(J62>0,J$78/J62*100,"")) -> 26.749961 | L62: 0.0014201389 | M62: =IF(L62="DNF","DNF",IF(L62>0,L$78/L62*100,"")) -> 87.856561 | N62: 0.0036990741 | O62: =IF(N62="DNF","DNF",IF(N62>0,N$78/N62*100,"")) -> 91.645807 | P62: 18 | Q62: =IF(P62="DNF","DNF",IF(P62<>"",P62/P$78*100,"")) -> 56.25 | R62: 0.00030694444 | S62: =IF(R62="DNF","DNF",IF(R62>0,R$78/R62*100,"")) -> 81.900452 | T62: =Birling!B41 -> 3 | U62: =Birling!C41 -> 26.785714 | V62: 0.0011875 | W62: =IF(V62="DNF","DNF",IF(V62>0,V$78/V62*100,"")) -> 50.682261 | X62: 0 | Y62: =IF(X62="DNF","DNF",IF(X62<>"",X62/X$78*100,"")) -> 0 | Z62: 0.00047326389 | AA62: =IF(Z62="DNF","DNF",IF(Z62>0,Z$78/Z62*100,"")) -> 21.080949 | AB62: 0.0023831019 | AC62: =IF(AB62="DNF","DNF",IF(AB62>0,AB$78/AB62*100,"")) -> 19.830015 | AD62: 0.00085416667 | AE62: =IF(AD62="DNF","DNF",IF(AD62>0,AD$78/AD62*100,"")) -> 76.96477 | AF62: 0.0011712963 | AG62: =IF(AF62="DNF","DNF",IF(AF62>0,AF$78/AF62*100,"")) -> 76.87747 | AH62: 0.0055324074 | AI62: =IF(AH62="DNF","DNF",IF(AH62>0,AH$78/AH62*100,"")) -> 20.585774 | AJ62: 0.0033344907 | AK62: =IF(AJ62="DNF","DNF",IF(AJ62>0,AJ$78/AJ62*100,"")) -> 97.188476 | AL62: 0.0044259259 | AM62: =IF(AL62="DNF","DNF",IF(AL62>0,AL$78/AL62*100,"")) -> 84.544979 | AO62: =A62 -> Dartmouth B | AP62: =SUM(C62,E62,G62,I62,K62,M62,O62,Q62,S62,U62,W62,Y62,AA62,AC62,AE62,AG62,AI62,AK62,AM62) -> 1103.5764 | AQ62: =RANK(AP62,$AP$62:$AP$73,0) -> 5 | AR62: 1 | AS62: =INDEX($AO$62:$AO$71,MATCH(AR62,$AQ$62:$AQ$71,0)) -> Paul Smith's M1 | AT62: =INDEX($AP$62:$AP$71,MATCH(AS62,$AO$62:$AO$71,0)) -> 1560.0532
...

Sheet Birling
A1: J&J | B1: Best time | C1: Score from final
A2: Teams
A3: Colby A | B3: 2.5 | C3: =B3/$B$9*80 -> 27.777778
A4: Dartmouth A | B4: 3.5 | C4: =B4/$B$9*80 -> 38.888889
A5: Paul Smith's J&J1 | B5: 70 | C5: 100
A6: Ranger J&J | B6: 40.5 | C6: 90
A7: UConn J&J A | B7: 2.5 | C7: =B7/$B$9*80 -> 27.777778
A8: UNH J | B8: 3.1 | C8: =B8/$B$9*80 -> 34.444444
A9: UVM | B9: 7.2 | C9: 80
A10: Colby B | B10: 3.1 | C10: =B10/$B$9*80 -> 34.444444
A11: Paul Smith's J&J2 | B11: 2.4 | C11: =B11/$B$9*80 -> 26.666667
A12: UConn J&J B | B12: 3.9 | C12: =B12/$B$9*80 -> 43.333333
A13: UNH K | B13: 43.1 | C13: 85
A14: Colby C | B14: 2.1 | C14: =B14/$B$9*80 -> 23.333333
A19: Dartmouth Alum A | B19: 1.4 | C19: =B19/$B$9*80 -> 15.555556
A20: Colby Alum | C20: =B20/$B$9*80 -> 0
A21: Dartmouth Alum B | B21: 1.7 | C21: =B21/$B$9*80 -> 18.888889
A29: Birl-Off
A30: 1st Place | B30: Paul Smith's J&J1
A31: Result
A32: 2nd Place | B32: Ranger J&J
A33: Result
A34: 3rd Place | B34: UNH K
A35: Result
A36: 4th Place | B36: UVM
A37: Result
A39: Other UGrad Teams
A40: Teams
A41: Dartmouth B | B41: 3 | C41: =B41/$B$43*100 -> 26.785714
A42: Paul Smith's M1 | B42: 2.6 | C42: =B42/$B$43*100 -> 23.214286
A43: Ranger Men | B43: 11.2 | C43: 100
A44: Paul Smith's M2 | B44: 1.6 | C44: =B44/$B$43*100 -> 14.285714
A45: Dartmouth C | B45: 2.1 | C45: =B45/$B$43*100 -> 18.75
A46: UNH Men's | B46: 1.5 | C46: =B46/$B$43*100 -> 13.392857
