Workbook

Sheet Dartmouth WW 2018
A1: Men's | B1: Singles Canoeing | D1: Doubles Canoeing | F1: Portage Canoeing | H1: Team Pulp Toss | J1: Log Rolling | L1: Packboard Relay w/ Firebuild | N1: Axe Throw | P1: Single Buck | R1: Birling | T1: Chain Throw | V1: Disc Stack | X1: Vertical Chop | Z1: Scoot Load | AB1: Crosscut Sawing | AD1: Team Bucksaw | AF1: Horizontal Chop | AH1: Splitting | AJ1: Pole Climb | AL1: Crosscut to Death
A2: Teams | B2: Time | C2: Score | D2: Time | E2: Score | F2: Time | G2: Score | H2: Time | I2: Score | J2: Time | K2: Score | L2: Time | M2: Score | N2: Mark | O2: Score | P2: Time | Q2: Score | R2: Time | S2: Score | T2: Time | U2: Score | V2: Raw Pts | W2: Score | X2: Time | Y2: Score | Z2: Time | AA2: Score | AB2: Time | AC2: Score | AD2: Time | AE2: Score | AF2: Time | AG2: Score | AH2: Time | AI2: Score | AJ2: Time | AK2: Score | AL2: Time | AM2: Score | AO2: TEAM | AP2: TOTAL | AQ2: RANK | AR2: Rank | AS2: Team | AT2: Score
A3: FLCC | B3: 0.002153125 | C3: =IF(B3="DNF","DNF",IF(B3>0,B$29/B3*100,"")) -> 100 | D3: 0.0017842593 | E3: =IF(D3="DNF","DNF",IF(D3>0,D$29/D3*100,"")) -> 98.949144 | F3: 0.0020732639 | G3: =IF(F3="DNF","DNF",IF(F3>0,F$29/F3*100,"")) -> 95.651203 | H3: 0.0025746528 | I3: =IF(H3="DNF","DNF",IF(H3>0,H$29/H3*100,"")) -> 64.92695 | J3: 0.00088761574 | K3: =IF(J3="DNF","DNF",IF(J3>0,J$29/J3*100,"")) -> 91.726431 | L3: 0.0065149306 | M3: =IF(L3="DNF","DNF",IF(L3>0,L$29/L3*100,"")) -> 75.821208 | N3: 6 | O3: =IF(N3="DNF","DNF",IF(N3<>"",N3/N$29*100,"")) -> 22.222222 | P3: 0.00021030093 | Q3: =IF(P3="DNF","DNF",IF(P3>0,P$29/P3*100,"")) -> 83.434232 | R3: =Birling!B3 -> 54.31 | S3: =Birling!C3 -> 16.752651 | T3: 0.0010907407 | U3: =IF(T3="DNF","DNF",IF(T3>0,T$29/T3*100,"")) -> 76.549236 | V3: 0 | W3: =IF(V3="DNF","DNF",IF(V3<>"",V3/V$29*100,"")) -> 0 | X3: 0.0015784722 | Y3: =IF(X3="DNF","DNF",IF(X3>0,X$29/X3*100,"")) -> 27.357384 | Z3: 0.00055451389 | AA3: =IF(Z3="DNF","DNF",IF(Z3>0,Z$29/Z3*100,"")) -> 92.391985 | AB3: 0.00056649306 | AC3: =IF(AB3="DNF","DNF",IF(AB3>0,AB$29/AB3*100,"")) -> 76.391868 | AD3: 0.00071087963 | AE3: =IF(AD3="DNF","DNF",IF(AD3>0,AD$29/AD3*100,"")) -> 89.791599 | AF3: 0.0012633102 | AG3: =IF(AF3="DNF","DNF",IF(AF3>0,AF$29/AF3*100,"")) -> 53.055428 | AH3: 0.0020175926 | AI3: =IF(AH3="DNF","DNF",IF(AH3>0,AH$29/AH3*100,"")) -> 87.058284 | AJ3: 9.6990741e-05 | AK3: =IF(AJ3="DNF","DNF",IF(AJ3>0,AJ$29/AJ3*100,"")) -> 72.792363 | AL3: 0.00041689815 | AM3: =IF(AL3="DNF","DNF",IF(AL3>0,AL$29/AL3*100,"")) -> 86.118823 | AO3: =$A3 -> FLCC | AP3: =SUM(C3,E3,G3,I3,K3,AI3,O3,Q3,U3,Y3,S3,,W3,AC3,AG3,AK3,AA3,AE3,M3, AM3) -> 1310.991 | AQ3: =RANK(AP3,$AP$3:$AP$24,0) -> 5 | AR3: 1 | AS3: =INDEX($AO$3:AO22,MATCH(AR3,$AQ$3:$AQ$22,0)) -> Paul Smiths | AT3: =INDEX($AP$3:$AP$22,MATCH(AS3,$AO$3:$AO$22,0)) -> 1715.3172
A4: Alfred State | B4: 0.0022112269 | C4: =IF(B4="DNF","DNF",IF(B4>0,B$29/B4*100,"")) -> 97.372416 | D4: 0.0019854167 | E4: =IF(D4="DNF","DNF",IF(D4>0,D$29/D4*100,"")) -> 88.923866 | F4: 0.0022127315 | G4: =IF(F4="DNF","DNF",IF(F4>0,F$29/F4*100,"")) -> 89.622345 | H4: 0.0020315972 | I4: =IF(H4="DNF","DNF",IF(H4>0,H$29/H4*100,"")) -> 82.282231 | J4: 0.00081417824 | K4: =IF(J4="DNF","DNF",IF(J4>0,J$29/J4*100,"")) -> 100 | L4: 0.0053094907 | M4: =IF(L4="DNF","DNF",IF(L4>0,L$29/L4*100,"")) -> 93.035271 | N4: 24 | O4: =IF(N4="DNF","DNF",IF(N4<>"",N4/N$29*100,"")) -> 88.888889 | P4: 0.00027407407 | Q4: =IF(P4="DNF","DNF",IF(P4>0,P$29/P4*100,"")) -> 64.02027 | R4: =Birling!B4 -> 42.6 | S4: =Birling!C4 -> 13.140544 | T4: 0.0011349537 | U4: =IF(T4="DNF","DNF",IF(T4>0,T$29/T4*100,"")) -> 73.567204 | V4: 24 | W4: =IF(V4="DNF","DNF",IF(V4<>"",V4/V$29*100,"")) -> 100 | X4: 0.00052916667 | Y4: =IF(X4="DNF","DNF",IF(X4>0,X$29/X4*100,"")) -> 81.605424 | Z4: 0.00062077546 | AA4: =IF(Z4="DNF","DNF",IF(Z4>0,Z$29/Z4*100,"")) -> 82.530064 | AB4: 0.00043275463 | AC4: =IF(AB4="DNF","DNF",IF(AB4>0,AB$29/AB4*100,"")) -> 100 | AD4: 0.0006556713 | AE4: =IF(AD4="DNF","DNF",IF(AD4>0,AD$29/AD4*100,"")) -> 97.352162 | AF4: 0.00080555556 | AG4: =IF(AF4="DNF","DNF",IF(AF4>0,AF$29/AF4*100,"")) -> 83.204023 | AH4: 0.002212963 | AI4: =IF(AH4="DNF","DNF",IF(AH4>0,AH$29/AH4*100,"")) -> 79.372385 | AJ4: 0.00014050926 | AK4: =IF(AJ4="DNF","DNF",IF(AJ4>0,AJ$29/AJ4*100,"")) -> 50.247117 | AL4: 0.00042025463 | AM4: =IF(AL4="DNF","DNF",IF(AL4>0,AL$29/AL4*100,"")) -> 85.431011 | AO4: =$A4 -> Alfred State | AP4: =SUM(C4,E4,G4,I4,K4,AI4,O4,Q4,U4,Y4,S4,,W4,AC4,AG4,AK4,AA4,AE4,M4, AM4) -> 1550.5952 | AQ4: =RANK(AP4,$AP$3:$AP$24,0) -> 3 | AR4: 2 | AS4: =INDEX($AO$3:AO23,MATCH(AR4,$AQ$3:$AQ$22,0)) -> ESF | AT4: =INDEX($AP$3:$AP$22,MATCH(AS4,$AO$3:$AO$22,0)) -> 1653.8794
A5: ESF | B5: 0.0022825231 | C5: =IF(B5="DNF","DNF",IF(B5>0,B$29/B5*100,"")) -> 94.330916 | D5: 0.0017655093 | E5: =IF(D5="DNF","DNF",IF(D5>0,D$29/D5*100,"")) -> 100 | F5: 0.0019831019 | G5: =IF(F5="DNF","DNF",IF(F5>0,F$29/F5*100,"")) -> 100 | H5: 0.0019858796 | I5: =IF(H5="DNF","DNF",IF(H5>0,H$29/H5*100,"")) -> 84.176477 | J5: 0.00082413194 | K5: =IF(J5="DNF","DNF",IF(J5>0,J$29/J5*100,"")) -> 98.79222 | L5: 0.0055255208 | M5: =IF(L5="DNF","DNF",IF(L5>0,L$29/L5*100,"")) -> 89.397891 | N5: 27 | O5: =IF(N5="DNF","DNF",IF(N5<>"",N5/N$29*100,"")) -> 100 | P5: 0.00021354167 | Q5: =IF(P5="DNF","DNF",IF(P5>0,P$29/P5*100,"")) -> 82.168022 | R5: =Birling!B5 -> 113.57 | S5: =Birling!C5 -> 90 | T5: 0.0012144676 | U5: =IF(T5="DNF","DNF",IF(T5>0,T$29/T5*100,"")) -> 68.750596 | V5: 12 | W5: =IF(V5="DNF","DNF",IF(V5<>"",V5/V$29*100,"")) -> 50 | X5: 0.0004318287 | Y5: =IF(X5="DNF","DNF",IF(X5>0,X$29/X5*100,"")) -> 100 | Z5: 0.00062702546 | AA5: =IF(Z5="DNF","DNF",IF(Z5>0,Z$29/Z5*100,"")) -> 81.70743 | AB5: 0.00046875 | AC5: =IF(AB5="DNF","DNF",IF(AB5>0,AB$29/AB5*100,"")) -> 92.320988 | AD5: 0.00072349537 | AE5: =IF(AD5="DNF","DNF",IF(AD5>0,AD$29/AD5*100,"")) -> 88.225884 | AF5: 0.00076979167 | AG5: =IF(AF5="DNF","DNF",IF(AF5>0,AF$29/AF5*100,"")) -> 87.069614 | AH5: 0.0025232639 | AI5: =IF(AH5="DNF","DNF",IF(AH5>0,AH$29/AH5*100,"")) -> 69.611486 | AJ5: 8.1828704e-05 | AK5: =IF(AJ5="DNF","DNF",IF(AJ5>0,AJ$29/AJ5*100,"")) -> 86.280057 | AL5: 0.0003943287 | AM5: =IF(AL5="DNF","DNF",IF(AL5>0,AL$29/AL5*100,"")) -> 91.047843 | AO5: =$A5 -> ESF | AP5: =SUM(C5,E5,G5,I5,K5,AI5,O5,Q5,U5,Y5,S5,,W5,AC5,AG5,AK5,AA5,AE5,M5, AM5) -> 1653.8794 | AQ5: =RANK(AP5,$AP$3:$AP$24,0) -> 2 | AR5: 3 | AS5: =INDEX($AO$3:AO24,MATCH(AR5,$AQ$3:$AQ$22,0)) -> Alfred State | AT5: =INDEX($AP$3:$AP$22,MATCH(AS5,$AO$3:$AO$22,0)) -> 1550.5952
A6: Morrisville | B6: 0.0024517361 | C6: =IF(B6="DNF","DNF",IF(B6>0,B$29/B6*100,"")) -> 87.820422 | D6: 0.0029268519 | E6: =IF(D6="DNF","DNF",IF(D6>0,D$29/D6*100,"")) -> 60.321101 | F6: 0.0022694444 | G6: =IF(F6="DNF","DNF",IF(F6>0,F$29/F6*100,"")) -> 87.382701 | H6: 0.0031773148 | I6: =IF(H6="DNF","DNF",IF(H6>0,H$29/H6*100,"")) -> 52.611832 | J6: 0.00098125 | K6: =IF(J6="DNF","DNF",IF(J6>0,J$29/J6*100,"")) -> 82.973579 | L6: 0.0065420718 | M6: =IF(L6="DNF","DNF",IF(L6>0,L$29/L6*100,"")) -> 75.506648 | N6: 22 | O6: =IF(N6="DNF","DNF",IF(N6<>"",N6/N$29*100,"")) -> 81.481481 | P6: 0.00051157407 | Q6: =IF(P6="DNF","DNF",IF(P6>0,P$29/P6*100,"")) -> 34.298643 | R6: =Birling!B6 -> 3 | S6: =Birling!C6 -> 0.9253904 | T6: 0.0019251157 | U6: =IF(T6="DNF","DNF",IF(T6>0,T$29/T6*100,"")) -> 43.371611 | V6: 5 | W6: =IF(V6="DNF","DNF",IF(V6<>"",V6/V$29*100,"")) -> 20.833333 | X6: 0.00084305556 | Y6: =IF(X6="DNF","DNF",IF(X6>0,X$29/X6*100,"")) -> 51.221856 | Z6: 0.00079571759 | AA6: =IF(Z6="DNF","DNF",IF(Z6>0,Z$29/Z6*100,"")) -> 64.385455 | AB6: 0.00081087963 | AC6: =IF(AB6="DNF","DNF",IF(AB6>0,AB$29/AB6*100,"")) -> 53.368541 | AD6: 0.0011451389 | AE6: =IF(AD6="DNF","DNF",IF(AD6>0,AD$29/AD6*100,"")) -> 55.740853 | AF6: 0.0012904514 | AG6: =IF(AF6="DNF","DNF",IF(AF6>0,AF$29/AF6*100,"")) -> 51.939549 | AH6: 0.0020053241 | AI6: =IF(AH6="DNF","DNF",IF(AH6>0,AH$29/AH6*100,"")) -> 87.590904 | AJ6: 0.00011157407 | AK6: =IF(AJ6="DNF","DNF",IF(AJ6>0,AJ$29/AJ6*100,"")) -> 63.278008 | AL6: 0.00076863426 | AM6: =IF(AL6="DNF","DNF",IF(AL6>0,AL$29/AL6*100,"")) -> 46.709833 | AO6: =$A6 -> Morrisville | AP6: =SUM(C6,E6,G6,I6,K6,AI6,O6,Q6,U6,Y6,S6,,W6,AC6,AG6,AK6,AA6,AE6,M6, AM6) -> 1101.7617 | AQ6: =RANK(AP6,$AP$3:$AP$24,0) -> 11 | AR6: 4 | AS6: =INDEX($AO$3:AO25,MATCH(AR6,$AQ$3:$AQ$22,0)) -> UNH | AT6: =INDEX($AP$3:$AP$22,MATCH(AS6,$AO$3:$AO$22,0)) -> 1313.6693
A7: UNH | B7: 0.0024553241 | C7: =IF(B7="DNF","DNF",IF(B7>0,B$29/B7*100,"")) -> 87.69209 | D7: 0.0023527778 | E7: =IF(D7="DNF","DNF",IF(D7>0,D$29/D7*100,"")) -> 75.039355 | F7: 0.0028517361 | G7: =IF(F7="DNF","DNF",IF(F7>0,F$29/F7*100,"")) -> 69.54016 | H7: 0.0029519676 | I7: =IF(H7="DNF","DNF",IF(H7>0,H$29/H7*100,"")) -> 56.628112 | J7: 0.0010244792 | K7: =IF(J7="DNF","DNF",IF(J7>0,J$29/J7*100,"")) -> 79.472406 | L7: 0.0054344329 | M7: =IF(L7="DNF","DNF",IF(L7>0,L$29/L7*100,"")) -> 90.896312 | N7: 27 | O7: =IF(N7="DNF","DNF",IF(N7<>"",N7/N$29*100,"")) -> 100 | P7: 0.00020277778 | Q7: =IF(P7="DNF","DNF",IF(P7>0,P$29/P7*100,"")) -> 86.52968 | R7: =Birling!B7 -> 137.41 | S7: =Birling!C7 -> 85 | T7: 0.0018555556 | U7: =IF(T7="DNF","DNF",IF(T7>0,T$29/T7*100,"")) -> 44.997505 | V7: 11 | W7: =IF(V7="DNF","DNF",IF(V7<>"",V7/V$29*100,"")) -> 45.833333 | X7: 0.00087372685 | Y7: =IF(X7="DNF","DNF",IF(X7>0,X$29/X7*100,"")) -> 49.423765 | Z7: 0.00077905093 | AA7: =IF(Z7="DNF","DNF",IF(Z7>0,Z$29/Z7*100,"")) -> 65.762888 | AB7: 0.00054641204 | AC7: =IF(AB7="DNF","DNF",IF(AB7>0,AB$29/AB7*100,"")) -> 79.199322 | AD7: 0.0008130787 | AE7: =IF(AD7="DNF","DNF",IF(AD7>0,AD$29/AD7*100,"")) -> 78.505338 | AF7: 0.0013358796 | AG7: =IF(AF7="DNF","DNF",IF(AF7>0,AF$29/AF7*100,"")) -> 50.17328 | AH7: 0.0027898148 | AI7: =IF(AH7="DNF","DNF",IF(AH7>0,AH$29/AH7*100,"")) -> 62.960504 | AJ7: 0.0001880787 | AK7: =IF(AJ7="DNF","DNF",IF(AJ7>0,AJ$29/AJ7*100,"")) -> 37.538462 | AL7: 0.00052430556 | AM7: =IF(AL7="DNF","DNF",IF(AL7>0,AL$29/AL7*100,"")) -> 68.476821 | AO7: =$A7 -> UNH | AP7: =SUM(C7,E7,G7,I7,K7,AI7,O7,Q7,U7,Y7,S7,,W7,AC7,AG7,AK7,AA7,AE7,M7, AM7) -> 1313.6693 | AQ7: =RANK(AP7,$AP$3:$AP$24,0) -> 4 | AR7: 5 | AS7: =INDEX($AO$3:AO26,MATCH(AR7,$AQ$3:$AQ$22,0)) -> FLCC | AT7: =INDEX($AP$3:$AP$22,MATCH(AS7,$AO$3:$AO$22,0)) -> 1310.991
A8: Unity | B8: 0.0025434028 | C8: =IF(B8="DNF","DNF",IF(B8>0,B$29/B8*100,"")) -> 84.65529 | D8: 0.0031752315 | E8: =IF(D8="DNF","DNF",IF(D8>0,D$29/D8*100,"")) -> 55.602537 | F8: 0.0026394676 | G8: =IF(F8="DNF","DNF",IF(F8>0,F$29/F8*100,"")) -> 75.132646 | H8: 0.0019413194 | I8: =IF(H8="DNF","DNF",IF(H8>0,H$29/H8*100,"")) -> 86.108627 | J8: 0.00089409722 | K8: =IF(J8="DNF","DNF",IF(J8>0,J$29/J8*100,"")) -> 91.061489 | L8: 0.010570312 | M8: =IF(L8="DNF","DNF",IF(L8>0,L$29/L8*100,"")) -> 46.731817 | N8: 10 | O8: =IF(N8="DNF","DNF",IF(N8<>"",N8/N$29*100,"")) -> 37.037037 | P8: 0.00023194444 | Q8: =IF(P8="DNF","DNF",IF(P8>0,P$29/P8*100,"")) -> 75.648703 | R8: =Birling!B8 -> 18.28 | S8: =Birling!C8 -> 5.6387122 | T8: 0.0017201389 | U8: =IF(T8="DNF","DNF",IF(T8>0,T$29/T8*100,"")) -> 48.5399 | V8: 17 | W8: =IF(V8="DNF","DNF",IF(V8<>"",V8/V$29*100,"")) -> 70.833333 | X8: 0.0015082176 | Y8: =IF(X8="DNF","DNF",IF(X8>0,X$29/X8*100,"")) -> 28.631724 | Z8: 0.00075416667 | AA8: =IF(Z8="DNF","DNF",IF(Z8>0,Z$29/Z8*100,"")) -> 67.932781 | AB8: 0.00046597222 | AC8: =IF(AB8="DNF","DNF",IF(AB8>0,AB$29/AB8*100,"")) -> 92.871336 | AD8: 0.00073796296 | AE8: =IF(AD8="DNF","DNF",IF(AD8>0,AD$29/AD8*100,"")) -> 86.496236 | AF8: 0.00086354167 | AG8: =IF(AF8="DNF","DNF",IF(AF8>0,AF$29/AF8*100,"")) -> 77.616941 | AH8: 0.0026027778 | AI8: =IF(AH8="DNF","DNF",IF(AH8>0,AH$29/AH8*100,"")) -> 67.484881 | AJ8: 8.75e-05 | AK8: =IF(AJ8="DNF","DNF",IF(AJ8>0,AJ$29/AJ8*100,"")) -> 80.687831 | AL8: 0.00035902778 | AM8: =IF(AL8="DNF","DNF",IF(AL8>0,AL$29/AL8*100,"")) -> 100 | AO8: =$A8 -> Unity | AP8: =SUM(C8,E8,G8,I8,K8,AI8,O8,Q8,U8,Y8,S8,,W8,AC8,AG8,AK8,AA8,AE8,M8, AM8) -> 1278.7118 | AQ8: =RANK(AP8,$AP$3:$AP$24,0) -> 6 | AR8: 6 | AS8: =INDEX($AO$3:AO27,MATCH(AR8,$AQ$3:$AQ$22,0)) -> Unity | AT8: =INDEX($AP$3:$AP$22,MATCH(AS8,$AO$3:$AO$22,0)) -> 1278.7118
A9: UVM | B9: 0.002349537 | C9: =IF(B9="DNF","DNF",IF(B9>0,B$29/B9*100,"")) -> 91.640394 | D9: 0.0022768519 | E9: =IF(D9="DNF","DNF",IF(D9>0,D$29/D9*100,"")) -> 77.541684 | F9: 0.0039228009 | G9: =IF(F9="DNF","DNF",IF(F9>0,F$29/F9*100,"")) -> 50.553212 | H9: 0.0028869213 | I9: =IF(H9="DNF","DNF",IF(H9>0,H$29/H9*100,"")) -> 57.904021 | J9: 0.00096965278 | K9: =IF(J9="DNF","DNF",IF(J9>0,J$29/J9*100,"")) -> 83.965958 | L9: 0.0067204282 | M9: =IF(L9="DNF","DNF",IF(L9>0,L$29/L9*100,"")) -> 73.502743 | N9: 14 | O9: =IF(N9="DNF","DNF",IF(N9<>"",N9/N$29*100,"")) -> 51.851852 | P9: 0.00031342593 | Q9: =IF(P9="DNF","DNF",IF(P9>0,P$29/P9*100,"")) -> 55.982275 | R9: =Birling!B9 -> 6.81 | S9: =Birling!C9 -> 2.1006362 | T9: 0.0013288194 | U9: =IF(T9="DNF","DNF",IF(T9>0,T$29/T9*100,"")) -> 62.834248 | V9: 0 | W9: =IF(V9="DNF","DNF",IF(V9<>"",V9/V$29*100,"")) -> 0 | X9: 0.0011994213 | Y9: =IF(X9="DNF","DNF",IF(X9>0,X$29/X9*100,"")) -> 36.003088 | Z9: 0.00071111111 | AA9: =IF(Z9="DNF","DNF",IF(Z9>0,Z$29/Z9*100,"")) -> 72.045898 | AB9: 0.0014594907 | AC9: =IF(AB9="DNF","DNF",IF(AB9>0,AB$29/AB9*100,"")) -> 29.651071 | AD9: 0.001205787 | AE9: =IF(AD9="DNF","DNF",IF(AD9>0,AD$29/AD9*100,"")) -> 52.937224 | AF9: 0.00098368056 | AG9: =IF(AF9="DNF","DNF",IF(AF9>0,AF$29/AF9*100,"")) -> 68.137428 | AH9: 0.0033163194 | AI9: =IF(AH9="DNF","DNF",IF(AH9>0,AH$29/AH9*100,"")) -> 52.964786 | AJ9: 0.00034525463 | AK9: =IF(AJ9="DNF","DNF",IF(AJ9>0,AJ$29/AJ9*100,"")) -> 20.449212 | AL9: 0.0013895833 | AM9: =IF(AL9="DNF","DNF",IF(AL9>0,AL$29/AL9*100,"")) -> 25.837081 | AO9: =$A9 -> UVM | AP9: =SUM(C9,E9,G9,I9,K9,AI9,O9,Q9,U9,Y9,S9,,W9,AC9,AG9,AK9,AA9,AE9,M9, AM9) -> 965.90281 | AQ9: =RANK(AP9,$AP$3:$AP$24,0) -> 12 | AR9: 7 | AS9: =INDEX($AO$3:AO28,MATCH(AR9,$AQ$3:$AQ$22,0)) -> Colby | AT9: =INDEX($AP$3:$AP$22,MATCH(AS9,$AO$3:$AO$22,0)) -> 1227.6189
A10: Cobleskill | B10: 0.0029137731 | C10: =IF(B10="DNF","DNF",IF(B10>0,B$29/B10*100,"")) -> 73.894737 | D10: 0.002159375 | E10: =IF(D10="DNF","DNF",IF(D10>0,D$29/D10*100,"")) -> 81.760197 | F10: 0.0020104167 | G10: =IF(F10="DNF","DNF",IF(F10>0,F$29/F10*100,"")) -> 98.641336 | H10: 0.002028588 | I10: =IF(H10="DNF","DNF",IF(H10>0,H$29/H10*100,"")) -> 82.404291 | J10: 0.00092314815 | K10: =IF(J10="DNF","DNF",IF(J10>0,J$29/J10*100,"")) -> 88.195838 | L10: 0.0085900463 | M10: =IF(L10="DNF","DNF",IF(L10>0,L$29/L10*100,"")) -> 57.504918 | N10: 10 | O10: =IF(N10="DNF","DNF",IF(N10<>"",N10/N$29*100,"")) -> 37.037037 | P10: 0.00047326389 | Q10: =IF(P10="DNF","DNF",IF(P10>0,P$29/P10*100,"")) -> 37.075079 | R10: =Birling!B10 -> 3.03 | S10: =Birling!C10 -> 0.9346443 | T10: 0.0020582176 | U10: =IF(T10="DNF","DNF",IF(T10>0,T$29/T10*100,"")) -> 40.566833 | V10: 18 | W10: =IF(V10="DNF","DNF",IF(V10<>"",V10/V$29*100,"")) -> 75 | X10: 0.00091990741 | Y10: =IF(X10="DNF","DNF",IF(X10>0,X$29/X10*100,"")) -> 46.942627 | Z10: 0.00052899306 | AA10: =IF(Z10="DNF","DNF",IF(Z10>0,Z$29/Z10*100,"")) -> 96.84936 | AB10: 0.00057847222 | AC10: =IF(AB10="DNF","DNF",IF(AB10>0,AB$29/AB10*100,"")) -> 74.809924 | AD10: 0.0013537037 | AE10: =IF(AD10="DNF","DNF",IF(AD10>0,AD$29/AD10*100,"")) -> 47.152873 | AF10: 0.0012179398 | AG10: =IF(AF10="DNF","DNF",IF(AF10>0,AF$29/AF10*100,"")) -> 55.031835 | AH10: 0.0029505787 | AI10: =IF(AH10="DNF","DNF",IF(AH10>0,AH$29/AH10*100,"")) -> 59.530067 | AJ10: 0.00012858796 | AK10: =IF(AJ10="DNF","DNF",IF(AJ10>0,AJ$29/AJ10*100,"")) -> 54.905491 | AL10: 0.00076226852 | AM10: =IF(AL10="DNF","DNF",IF(AL10>0,AL$29/AL10*100,"")) -> 47.099909 | AO10: =$A10 -> Cobleskill | AP10: =SUM(C10,E10,G10,I10,K10,AI10,O10,Q10,U10,Y10,S10,,W10,AC10,AG10,AK10,AA10,AE10,M10, AM10) -> 1155.337 | AQ10: =RANK(AP10,$AP$3:$AP$24,0) -> 10 | AR10: 8 | AS10: =INDEX($AO$3:AO29,MATCH(AR10,$AQ$3:$AQ$22,0)) -> Ranger | AT10: =INDEX($AP$3:$AP$22,MATCH(AS10,$AO$3:$AO$22,0)) -> 1216.4958
A11: Dartmouth | B11: 0.0030363426 | C11: =IF(B11="DNF","DNF",IF(B11>0,B$29/B11*100,"")) -> 70.911794 | D11: 0.0022674769 | E11: =IF(D11="DNF","DNF",IF(D11>0,D$29/D11*100,"")) -> 77.862284 | F11: 0.0026228009 | G11: =IF(F11="DNF","DNF",IF(F11>0,F$29/F11*100,"")) -> 75.610079 | H11: 0.0070381944 | I11: =IF(H11="DNF","DNF",IF(H11>0,H$29/H11*100,"")) -> 23.751028 | J11: 0.0014077546 | K11: =IF(J11="DNF","DNF",IF(J11>0,J$29/J11*100,"")) -> 57.835238 | L11: 0.0099231481 | M11: =IF(L11="DNF","DNF",IF(L11>0,L$29/L11*100,"")) -> 49.779556 | N11: 11 | O11: =IF(N11="DNF","DNF",IF(N11<>"",N11/N$29*100,"")) -> 40.740741 | P11: 0.00051516204 | Q11: =IF(P11="DNF","DNF",IF(P11>0,P$29/P11*100,"")) -> 34.059762 | R11: =Birling!B11 -> 14.12 | S11: =Birling!C11 -> 4.3555041 | T11: 0.0018670139 | U11: =IF(T11="DNF","DNF",IF(T11>0,T$29/T11*100,"")) -> 44.721344 | V11: 4 | W11: =IF(V11="DNF","DNF",IF(V11<>"",V11/V$29*100,"")) -> 16.666667 | X11: 0.005059375 | Y11: =IF(X11="DNF","DNF",IF(X11>0,X$29/X11*100,"")) -> 8.5352184 | Z11: 0.00098686343 | AA11: =IF(Z11="DNF","DNF",IF(Z11>0,Z$29/Z11*100,"")) -> 51.914619 | AB11: 0.0011645833 | AC11: =IF(AB11="DNF","DNF",IF(AB11>0,AB$29/AB11*100,"")) -> 37.15961 | AD11: 0.0014383102 | AE11: =IF(AD11="DNF","DNF",IF(AD11>0,AD$29/AD11*100,"")) -> 44.379174 | AF11: 0.0023399306 | AG11: =IF(AF11="DNF","DNF",IF(AF11>0,AF$29/AF11*100,"")) -> 28.64421 | AH11: 0.0025944444 | AI11: =IF(AH11="DNF","DNF",IF(AH11>0,AH$29/AH11*100,"")) -> 67.701642 | AJ11: 0.0002037037 | AK11: =IF(AJ11="DNF","DNF",IF(AJ11>0,AJ$29/AJ11*100,"")) -> 34.659091 | AL11: 0.0010950231 | AM11: =IF(AL11="DNF","DNF",IF(AL11>0,AL$29/AL11*100,"")) -> 32.787232 | AO11: =$A11 -> Dartmouth | AP11: =SUM(C11,E11,G11,I11,K11,AI11,O11,Q11,U11,Y11,S11,,W11,AC11,AG11,AK11,AA11,AE11,M11, AM11) -> 802.07479 | AQ11: =RANK(AP11,$AP$3:$AP$24,0) -> 13 | AR11: 9 | AS11: =INDEX($AO$3:AO30,MATCH(AR11,$AQ$3:$AQ$22,0)) -> UMO | AT11: =INDEX($AP$3:$AP$22,MATCH(AS11,$AO$3:$AO$22,0)) -> 1157.0947
A12: Ranger | B12: 0.0024385417 | C12: =IF(B12="DNF","DNF",IF(B12>0,B$29/B12*100,"")) -> 88.2956 | D12: 0.0020896991 | E12: =IF(D12="DNF","DNF",IF(D12>0,D$29/D12*100,"")) -> 84.486292 | F12: 0.0024150463 | G12: =IF(F12="DNF","DNF",IF(F12>0,F$29/F12*100,"")) -> 82.114445 | H12: 0.0026278935 | I12: =IF(H12="DNF","DNF",IF(H12>0,H$29/H12*100,"")) -> 63.611539 | J12: 0.0011969907 | K12: =IF(J12="DNF","DNF",IF(J12>0,J$29/J12*100,"")) -> 68.018758 | L12: 0.0053876157 | M12: =IF(L12="DNF","DNF",IF(L12>0,L$29/L12*100,"")) -> 91.68618 | N12: 25 | O12: =IF(N12="DNF","DNF",IF(N12<>"",N12/N$29*100,"")) -> 92.592593 | P12: 0.00029803241 | Q12: =IF(P12="DNF","DNF",IF(P12>0,P$29/P12*100,"")) -> 58.873786 | R12: =Birling!B12 -> 4.81 | S12: =Birling!C12 -> 1.4837093 | T12: 0.0015222222 | U12: =IF(T12="DNF","DNF",IF(T12>0,T$29/T12*100,"")) -> 54.850973 | V12: 13 | W12: =IF(V12="DNF","DNF",IF(V12<>"",V12/V$29*100,"")) -> 54.166667 | X12: 0.0012915509 | Y12: =IF(X12="DNF","DNF",IF(X12>0,X$29/X12*100,"")) -> 33.434896 | Z12: 0.00055596065 | AA12: =IF(Z12="DNF","DNF",IF(Z12>0,Z$29/Z12*100,"")) -> 92.151556 | AB12: 0.00086388889 | AC12: =IF(AB12="DNF","DNF",IF(AB12>0,AB$29/AB12*100,"")) -> 50.093783 | AD12: 0.001597338 | AE12: =IF(AD12="DNF","DNF",IF(AD12>0,AD$29/AD12*100,"")) -> 39.960872 | AF12: 0.0011266204 | AG12: =IF(AF12="DNF","DNF",IF(AF12>0,AF$29/AF12*100,"")) -> 59.492501 | AH12: 0.0017564815 | AI12: =IF(AH12="DNF","DNF",IF(AH12>0,AH$29/AH12*100,"")) -> 100 | AJ12: 0.00017361111 | AK12: =IF(AJ12="DNF","DNF",IF(AJ12>0,AJ$29/AJ12*100,"")) -> 40.666667 | AL12: 0.00059328704 | AM12: =IF(AL12="DNF","DNF",IF(AL12>0,AL$29/AL12*100,"")) -> 60.515021 | AO12: =$A12 -> Ranger | AP12: =SUM(C12,E12,G12,I12,K12,AI12,O12,Q12,U12,Y12,S12,,W12,AC12,AG12,AK12,AA12,AE12,M12, AM12) -> 1216.4958 | AQ12: =RANK(AP12,$AP$3:$AP$24,0) -> 8 | AR12: 10 | AS12: =INDEX($AO$3:AO31,MATCH(AR12,$AQ$3:$AQ$22,0)) -> Cobleskill | AT12: =INDEX($AP$3:$AP$22,MATCH(AS12,$AO$3:$AO$22,0)) -> 1155.337
A13: Paul Smiths | B13: 0.0023694444 | C13: =IF(B13="DNF","DNF",IF(B13>0,B$29/B13*100,"")) -> 90.870457 | D13: 0.00213125 | E13: =IF(D13="DNF","DNF",IF(D13>0,D$29/D13*100,"")) -> 82.839144 | F13: 0.0024005787 | G13: =IF(F13="DNF","DNF",IF(F13>0,F$29/F13*100,"")) -> 82.609325 | H13: 0.0016716435 | I13: =IF(H13="DNF","DNF",IF(H13>0,H$29/H13*100,"")) -> 100 | J13: 0.00083478009 | K13: =IF(J13="DNF","DNF",IF(J13>0,J$29/J13*100,"")) -> 97.532062 | L13: 0.0049396991 | M13: =IF(L13="DNF","DNF",IF(L13>0,L$29/L13*100,"")) -> 100 | N13: 23 | O13: =IF(N13="DNF","DNF",IF(N13<>"",N13/N$29*100,"")) -> 85.185185 | P13: 0.00017546296 | Q13: =IF(P13="DNF","DNF",IF(P13>0,P$29/P13*100,"")) -> 100 | R13: =Birling!B13 -> 173.05 | S13: =Birling!C13 -> 100 | T13: 0.0008349537 | U13: =IF(T13="DNF","DNF",IF(T13>0,T$29/T13*100,"")) -> 100 | V13: 17 | W13: =IF(V13="DNF","DNF",IF(V13<>"",V13/V$29*100,"")) -> 70.833333 | X13: 0.00046527778 | Y13: =IF(X13="DNF","DNF",IF(X13>0,X$29/X13*100,"")) -> 92.810945 | Z13: 0.00068761574 | AA13: =IF(Z13="DNF","DNF",IF(Z13>0,Z$29/Z13*100,"")) -> 74.507659 | AB13: 0.00045775463 | AC13: =IF(AB13="DNF","DNF",IF(AB13>0,AB$29/AB13*100,"")) -> 94.538559 | AD13: 0.00063831019 | AE13: =IF(AD13="DNF","DNF",IF(AD13>0,AD$29/AD13*100,"")) -> 100 | AF13: 0.00067025463 | AG13: =IF(AF13="DNF","DNF",IF(AF13>0,AF$29/AF13*100,"")) -> 100 | AH13: 0.0023092593 | AI13: =IF(AH13="DNF","DNF",IF(AH13>0,AH$29/AH13*100,"")) -> 76.06255 | AJ13: 0.00010023148 | AK13: =IF(AJ13="DNF","DNF",IF(AJ13>0,AJ$29/AJ13*100,"")) -> 70.438799 | AL13: 0.00036979167 | AM13: =IF(AL13="DNF","DNF",IF(AL13>0,AL$29/AL13*100,"")) -> 97.089202 | AO13: =$A13 -> Paul Smiths | AP13: =SUM(C13,E13,G13,I13,K13,AI13,O13,Q13,U13,Y13,S13,,W13,AC13,AG13,AK13,AA13,AE13,M13, AM13) -> 1715.3172 | AQ13: =RANK(AP13,$AP$3:$AP$24,0) -> 1 | AR13: 11 | AS13: =INDEX($AO$3:AO32,MATCH(AR13,$AQ$3:$AQ$22,0)) -> Morrisville | AT13: =INDEX($AP$3:$AP$22,MATCH(AS13,$AO$3:$AO$22,0)) -> 1101.7617
A14: Colby | B14: 0.0025787037 | C14: =IF(B14="DNF","DNF",IF(B14>0,B$29/B14*100,"")) -> 83.496409 | D14: 0.0027556713 | E14: =IF(D14="DNF","DNF",IF(D14>0,D$29/D14*100,"")) -> 64.06821 | F14: 0.0030193287 | G14: =IF(F14="DNF","DNF",IF(F14>0,F$29/F14*100,"")) -> 65.680224 | H14: 0.0031430556 | I14: =IF(H14="DNF","DNF",IF(H14>0,H$29/H14*100,"")) -> 53.1853 | J14: 0.0011868634 | K14: =IF(J14="DNF","DNF",IF(J14>0,J$29/J14*100,"")) -> 68.599152 | L14: 0.0064519676 | M14: =IF(L14="DNF","DNF",IF(L14>0,L$29/L14*100,"")) -> 76.561127 | N14: 15 | O14: =IF(N14="DNF","DNF",IF(N14<>"",N14/N$29*100,"")) -> 55.555556 | P14: 0.00032511574 | Q14: =IF(P14="DNF","DNF",IF(P14>0,P$29/P14*100,"")) -> 53.969384 | R14: =Birling!B14 -> 16.72 | S14: =Birling!C14 -> 5.1575092 | T14: 0.001027662 | U14: =IF(T14="DNF","DNF",IF(T14>0,T$29/T14*100,"")) -> 81.247888 | V14: 11 | W14: =IF(V14="DNF","DNF",IF(V14<>"",V14/V$29*100,"")) -> 45.833333 | X14: 0.0010251157 | Y14: =IF(X14="DNF","DNF",IF(X14>0,X$29/X14*100,"")) -> 42.124873 | Z14: 0.00051232639 | AA14: =IF(Z14="DNF","DNF",IF(Z14>0,Z$29/Z14*100,"")) -> 100 | AB14: 0.000590625 | AC14: =IF(AB14="DNF","DNF",IF(AB14>0,AB$29/AB14*100,"")) -> 73.270625 | AD14: 0.00074988426 | AE14: =IF(AD14="DNF","DNF",IF(AD14>0,AD$29/AD14*100,"")) -> 85.121161 | AF14: 0.0015237269 | AG14: =IF(AF14="DNF","DNF",IF(AF14>0,AF$29/AF14*100,"")) -> 43.987847 | AH14: 0.0036398148 | AI14: =IF(AH14="DNF","DNF",IF(AH14>0,AH$29/AH14*100,"")) -> 48.257441 | AJ14: 7.0601852e-05 | AK14: =IF(AJ14="DNF","DNF",IF(AJ14>0,AJ$29/AJ14*100,"")) -> 100 | AL14: 0.00044050926 | AM14: =IF(AL14="DNF","DNF",IF(AL14>0,AL$29/AL14*100,"")) -> 81.50289 | AO14: =$A14 -> Colby | AP14: =SUM(C14,E14,G14,I14,K14,AI14,O14,Q14,U14,Y14,S14,,W14,AC14,AG14,AK14,AA14,AE14,M14, AM14) -> 1227.6189 | AQ14: =RANK(AP14,$AP$3:$AP$24,0) -> 7 | AR14: 12 | AS14: =INDEX($AO$3:AO33,MATCH(AR14,$AQ$3:$AQ$22,0)) -> UVM | AT14: =INDEX($AP$3:$AP$22,MATCH(AS14,$AO$3:$AO$22,0)) -> 965.90281
A15: UMO | B15: 0.0027748843 | C15: =IF(B15="DNF","DNF",IF(B15>0,B$29/B15*100,"")) -> 77.593326 | D15: 0.0029240741 | E15: =IF(D15="DNF","DNF",IF(D15>0,D$29/D15*100,"")) -> 60.378404 | F15: 0.0025175926 | G15: =IF(F15="DNF","DNF",IF(F15>0,F$29/F15*100,"")) -> 78.769768 | H15: 0.0025581019 | I15: =IF(H15="DNF","DNF",IF(H15>0,H$29/H15*100,"")) -> 65.347027 | J15: 0.0011383681 | K15: =IF(J15="DNF","DNF",IF(J15>0,J$29/J15*100,"")) -> 71.521529 | L15: 0.0064878472 | M15: =IF(L15="DNF","DNF",IF(L15>0,L$29/L15*100,"")) -> 76.137722 | N15: 18 | O15: =IF(N15="DNF","DNF",IF(N15<>"",N15/N$29*100,"")) -> 66.666667 | P15: 0.00036631944 | Q15: =IF(P15="DNF","DNF",IF(P15>0,P$29/P15*100,"")) -> 47.898894 | R15: =Birling!B15 -> 259.35 | S15: =Birling!C15 -> 80 | T15: 0.0017076389 | U15: =IF(T15="DNF","DNF",IF(T15>0,T$29/T15*100,"")) -> 48.895215 | V15: 18 | W15: =IF(V15="DNF","DNF",IF(V15<>"",V15/V$29*100,"")) -> 75 | X15: 0.0077266204 | Y15: =IF(X15="DNF","DNF",IF(X15>0,X$29/X15*100,"")) -> 5.5888433 | Z15: 0.0010116319 | AA15: =IF(Z15="DNF","DNF",IF(Z15>0,Z$29/Z15*100,"")) -> 50.643556 | AB15: 0.00076354167 | AC15: =IF(AB15="DNF","DNF",IF(AB15>0,AB$29/AB15*100,"")) -> 56.677278 | AD15: 0.0012685185 | AE15: =IF(AD15="DNF","DNF",IF(AD15>0,AD$29/AD15*100,"")) -> 50.319343 | AF15: 0.001180787 | AG15: =IF(AF15="DNF","DNF",IF(AF15>0,AF$29/AF15*100,"")) -> 56.76338 | AH15: 0.0022762731 | AI15: =IF(AH15="DNF","DNF",IF(AH15>0,AH$29/AH15*100,"")) -> 77.164794 | AJ15: 0.000140625 | AK15: =IF(AJ15="DNF","DNF",IF(AJ15>0,AJ$29/AJ15*100,"")) -> 50.205761 | AL15: 0.00058356481 | AM15: =IF(AL15="DNF","DNF",IF(AL15>0,AL$29/AL15*100,"")) -> 61.523205 | AO15: =$A15 -> UMO | AP15: =SUM(C15,E15,G15,I15,K15,AI15,O15,Q15,U15,Y15,S15,,W15,AC15,AG15,AK15,AA15,AE15,M15, AM15) -> 1157.0947 | AQ15: =RANK(AP15,$AP$3:$AP$24,0) -> 9 | AR15: 13 | AS15: =INDEX($AO$3:AO34,MATCH(AR15,$AQ$3:$AQ$22,0)) -> Dartmouth | AT15: =INDEX($AP$3:$AP$22,MATCH(AS15,$AO$3:$AO$22,0)) -> 802.07479
C16: =IF(B16="DNF","DNF",IF(B16>0,B$29/B16*100,"")) | E16: =IF(D16="DNF","DNF",IF(D16>0,D$29/D16*100,"")) | G16: =IF(F16="DNF","DNF",IF(F16>0,F$29/F16*100,"")) | I16: =IF(H16="DNF","DNF",IF(H16>0,H$29/H16*100,"")) | K16: =IF(J16="DNF","DNF",IF(J16>0,J$29/J16*100,"")) | M16: =IF(L16="DNF","DNF",IF(L16>0,L$29/L16*100,"")) | O16: =IF(N16="DNF","DNF",IF(N16<>"",N16/N$29*100,"")) | Q16: =IF(P16="DNF","DNF",IF(P16>0,P$29/P16*100,"")) | U16: =IF(T16="DNF","DNF",IF(T16>0,T$29/T16*100,"")) | W16: =IF(V16="DNF","DNF",IF(V16<>"",V16/V$29*100,"")) | Y16: =IF(X16="DNF","DNF",IF(X16>0,X$29/X16*100,"")) | AA16: =IF(Z16="DNF","DNF",IF(Z16>0,Z$29/Z16*100,"")) | AC16: =IF(AB16="DNF","DNF",IF(AB16>0,AB$29/AB16*100,"")) | AE16: =IF(AD16="DNF","DNF",IF(AD16>0,AD$29/AD16*100,"")) | AG16: =IF(AF16="DNF","DNF",IF(AF16>0,AF$29/AF16*100,"")) | AI16: =IF(AH16="DNF","DNF",IF(AH16>0,AH$29/AH16*100,"")) | AK16: =IF(AJ16="DNF","DNF",IF(AJ16>0,AJ$29/AJ16*100,"")) | AM16: =IF(AL16="DNF","DNF",IF(AL16>0,AL$29/AL16*100,""))
C17: =IF(B17="DNF","DNF",IF(B17>0,B$29/B17*100,"")) | E17: =IF(D17="DNF","DNF",IF(D17>0,D$29/D17*100,"")) | G17: =IF(F17="DNF","DNF",IF(F17>0,F$29/F17*100,"")) | I17: =IF(H17="DNF","DNF",IF(H17>0,H$29/H17*100,"")) | K17: =IF(J17="DNF","DNF",IF(J17>0,J$29/J17*100,"")) | M17: =IF(L17="DNF","DNF",IF(L17>0,L$29/L17*100,"")) | O17: =IF(N17="DNF","DNF",IF(N17<>"",N17/N$29*100,"")) | Q17: =IF(P17="DNF","DNF",IF(P17>0,P$29/P17*100,"")) | U17: =IF(T17="DNF","DNF",IF(T17>0,T$29/T17*100,"")) | W17: =IF(V17="DNF","DNF",IF(V17<>"",V17/V$29*100,"")) | Y17: =IF(X17="DNF","DNF",IF(X17>0,X$29/X17*100,"")) | AA17: =IF(Z17="DNF","DNF",IF(Z17>0,Z$29/Z17*100,"")) | AC17: =IF(AB17="DNF","DNF",IF(AB17>0,AB$29/AB17*100,"")) | AE17: =IF(AD17="DNF","DNF",IF(AD17>0,AD$29/AD17*100,"")) | AG17: =IF(AF17="DNF","DNF",IF(AF17>0,AF$29/AF17*100,"")) | AI17: =IF(AH17="DNF","DNF",IF(AH17>0,AH$29/AH17*100,"")) | AK17: =IF(AJ17="DNF","DNF",IF(AJ17>0,AJ$29/AJ17*100,"")) | AM17: =IF(AL17="DNF","DNF",IF(AL17>0,AL$29/AL17*100,""))
C18: =IF(B18="DNF","DNF",IF(B18>0,B$29/B18*100,"")) | E18: =IF(D18="DNF","DNF",IF(D18>0,D$29/D18*100,"")) | G18: =IF(F18="DNF","DNF",IF(F18>0,F$29/F18*100,"")) | I18: =IF(H18="DNF","DNF",IF(H18>0,H$29/H18*100,"")) | K18: =IF(J18="DNF","DNF",IF(J18>0,J$24/J18*100,"")) | M18: =IF(L18="DNF","DNF",IF(L18>0,L$29/L18*100,"")) | O18: =IF(N18="DNF","DNF",IF(N18<>"",N18/N$29*100,"")) | Q18: =IF(P18="DNF","DNF",IF(P18>0,P$24/P18*100,"")) | U18: =IF(T18="DNF","DNF",IF(T18>0,T$29/T18*100,"")) | W18: =IF(V18="DNF","DNF",IF(V18<>"",V18/V$29*100,"")) | Y18: =IF(X18="DNF","DNF",IF(X18>0,X$29/X18*100,"")) | AA18: =IF(Z18="DNF","DNF",IF(Z18>0,Z$24/Z18*100,"")) | AC18: =IF(AB18="DNF","DNF",IF(AB18>0,AB$29/AB18*100,"")) | AE18: =IF(AD18="DNF","DNF",IF(AD18>0,AD$29/AD18*100,"")) | AG18: =IF(AF18="DNF","DNF",IF(AF18>0,AF$29/AF18*100,"")) | AI18: =IF(AH18="DNF","DNF",IF(AH18>0,AH$29/AH18*100,"")) | AK18: =IF(AJ18="DNF","DNF",IF(AJ18>0,AJ$29/AJ18*100,"")) | AM18: =IF(AL18="DNF","DNF",IF(AL18>0,AL$29/AL18*100,""))
C20: =IF(B20="DNF","DNF",IF(B20>0,B$29/B20*100,"")) | E20: =IF(D20="DNF","DNF",IF(D20>0,D$29/D20*100,"")) | G20: =IF(F20="DNF","DNF",IF(F20>0,F$29/F20*100,"")) | I20: =IF(H20="DNF","DNF",IF(H20>0,H$29/H20*100,"")) | K20: =IF(J20="DNF","DNF",IF(J20>0,J$24/J20*100,"")) | M20: =IF(L20="DNF","DNF",IF(L20>0,L$29/L20*100,"")) | O20: =IF(N20="DNF","DNF",IF(N20<>"",N20/N$29*100,"")) | Q20: =IF(P20="DNF","DNF",IF(P20>0,P$24/P20*100,"")) | U20: =IF(T20="DNF","DNF",IF(T20>0,T$29/T20*100,"")) | W20: =IF(V20="DNF","DNF",IF(V20<>"",V20/V$29*100,"")) | Y20: =IF(X20="DNF","DNF",IF(X20>0,X$29/X20*100,"")) | AA20: =IF(Z20="DNF","DNF",IF(Z20>0,Z$24/Z20*100,"")) | AC20: =IF(AB20="DNF","DNF",IF(AB20>0,AB$29/AB20*100,"")) | AE20: =IF(AD20="DNF","DNF",IF(AD20>0,AD$29/AD20*100,"")) | AG20: =IF(AF20="DNF","DNF",IF(AF20>0,AF$29/AF20*100,"")) | AI20: =IF(AH20="DNF","DNF",IF(AH20>0,AH$29/AH20*100,"")) | AK20: =IF(AJ20="DNF","DNF",IF(AJ20>0,AJ$29/AJ20*100,"")) | AM20: =IF(AL20="DNF","DNF",IF(AL20>0,AL$29/AL20*100,""))
C21: =IF(B21="DNF","DNF",IF(B21>0,B$29/B21*100,"")) | E21: =IF(D21="DNF","DNF",IF(D21>0,D$29/D21*100,"")) | G21: =IF(F21="DNF","DNF",IF(F21>0,F$29/F21*100,"")) | I21: =IF(H21="DNF","DNF",IF(H21>0,H$29/H21*100,"")) | K21: =IF(J21="DNF","DNF",IF(J21>0,J$24/J21*100,"")) | M21: =IF(L21="DNF","DNF",IF(L21>0,L$29/L21*100,"")) | O21: =IF(N21="DNF","DNF",IF(N21<>"",N21/N$29*100,"")) | Q21: =IF(P21="DNF","DNF",IF(P21>0,P$24/P21*100,"")) | U21: =IF(T21="DNF","DNF",IF(T21>0,T$29/T21*100,"")) | W21: =IF(V21="DNF","DNF",IF(V21<>"",V21/V$29*100,"")) | Y21: =IF(X21="DNF","DNF",IF(X21>0,X$29/X21*100,"")) | AA21: =IF(Z21="DNF","DNF",IF(Z21>0,Z$24/Z21*100,"")) | AC21: =IF(AB21="DNF","DNF",IF(AB21>0,AB$29/AB21*100,"")) | AE21: =IF(AD21="DNF","DNF",IF(AD21>0,AD$29/AD21*100,"")) | AG21: =IF(AF21="DNF","DNF",IF(AF21>0,AF$29/AF21*100,"")) | AI21: =IF(AH21="DNF","DNF",IF(AH21>0,AH$29/AH21*100,"")) | AK21: =IF(AJ21="DNF","DNF",IF(AJ21>0,AJ$29/AJ21*100,"")) | AM21: =IF(AL21="DNF","DNF",IF(AL21>0,AL$29/AL21*100,""))
C22: =IF(B22="DNF","DNF",IF(B22>0,B$29/B22*100,"")) | E22: =IF(D22="DNF","DNF",IF(D22>0,D$29/D22*100,"")) | G22: =IF(F22="DNF","DNF",IF(F22>0,F$29/F22*100,"")) | I22: =IF(H22="DNF","DNF",IF(H22>0,H$29/H22*100,"")) | K22: =IF(J22="DNF","DNF",IF(J22>0,J$24/J22*100,"")) | M22: =IF(L22="DNF","DNF",IF(L22>0,L$29/L22*100,"")) | O22: =IF(N22="DNF","DNF",IF(N22<>"",N22/N$29*100,"")) | Q22: =IF(P22="DNF","DNF",IF(P22>0,P$24/P22*100,"")) | U22: =IF(T22="DNF","DNF",IF(T22>0,T$29/T22*100,"")) | W22: =IF(V22="DNF","DNF",IF(V22<>"",V22/V$29*100,"")) | Y22: =IF(X22="DNF","DNF",IF(X22>0,X$29/X22*100,"")) | AA22: =IF(Z22="DNF","DNF",IF(Z22>0,Z$24/Z22*100,"")) | AC22: =IF(AB22="DNF","DNF",IF(AB22>0,AB$29/AB22*100,"")) | AE22: =IF(AD22="DNF","DNF",IF(AD22>0,AD$29/AD22*100,"")) | AG22: =IF(AF22="DNF","DNF",IF(AF22>0,AF$29/AF22*100,"")) | AI22: =IF(AH22="DNF","DNF",IF(AH22>0,AH$29/AH22*100,"")) | AK22: =IF(AJ22="DNF","DNF",IF(AJ22>0,AJ$29/AJ22*100,"")) | AM22: =IF(AL22="DNF","DNF",IF(AL22>0,AL$29/AL22*100,""))
C24: =IF(B24="DNF","DNF",IF(B24>0,B$29/B24*100,"")) | E24: =IF(D24="DNF","DNF",IF(D24>0,D$29/D24*100,"")) | G24: =IF(F24="DNF","DNF",IF(F24>0,F$29/F24*100,"")) | I24: =IF(H24="DNF","DNF",IF(H24>0,H$29/H24*100,"")) | K24: =IF(J24="DNF","DNF",IF(J24>0,J$29/J24*100,"")) | M24: =IF(L24="DNF","DNF",IF(L24>0,L$29/L24*100,"")) | O24: =IF(N24="DNF","DNF",IF(N24<>"",N24/N$29*100,"")) | Q24: =IF(P24="DNF","DNF",IF(P24>0,P$29/P24*100,"")) | U24: =IF(T24="DNF","DNF",IF(T24>0,T$29/T24*100,"")) | W24: =IF(V24="DNF","DNF",IF(V24<>"",V24/V$29*100,"")) | Y24: =IF(X24="DNF","DNF",IF(X24>0,X$29/X24*100,"")) | AC24: =IF(AB24="DNF","DNF",IF(AB24>0,AB$29/AB24*100,"")) | AE24: =IF(AD24="DNF","DNF",IF(AD24>0,AD$29/AD24*100,"")) | AG24: =IF(AF24="DNF","DNF",IF(AF24>0,AF$29/AF24*100,"")) | AI24: =IF(AH24="DNF","DNF",IF(AH24>0,AH$29/AH24*100,"")) | AK24: =IF(AJ24="DNF","DNF",IF(AJ24>0,AJ$29/AJ24*100,"")) | AM24: =IF(AL24="DNF","DNF",IF(AL24>0,AL$29/AL24*100,""))
A25: Dartmouth Alum | B25: 0.0023283565 | C25: =IF(B25="DNF","DNF",IF(B25>0,B$29/B25*100,"")) -> 92.474027 | D25: 0.0017912037 | E25: =IF(D25="DNF","DNF",IF(D25>0,D$29/D25*100,"")) -> 98.565521 | F25: 0.0021695602 | G25: =IF(F25="DNF","DNF",IF(F25>0,F$29/F25*100,"")) -> 91.405708 | H25: 0.0076349537 | I25: =IF(H25="DNF","DNF",IF(H25>0,H$29/H25*100,"")) -> 21.894612 | J25: 0.0014789352 | K25: =IF(J25="DNF","DNF",IF(J25>0,J$29/J25*100,"")) -> 55.051651 | L25: 0.0078985532 | M25: =IF(L25="DNF","DNF",IF(L25>0,L$29/L25*100,"")) -> 62.539289 | N25: 0 | O25: =IF(N25="DNF","DNF",IF(N25<>"",N25/N$29*100,"")) -> 0 | P25: 0.00028333333 | Q25: =IF(P25="DNF","DNF",IF(P25>0,P$29/P25*100,"")) -> 61.928105 | R25: =Birling!B19 -> 20.69 | S25: =Birling!C19 -> 6.3821091 | T25: 0.00074594907 | U25: =IF(T25="DNF","DNF",IF(T25>0,T$29/T25*100,"")) -> 111.93173 | V25: 0 | W25: =IF(V25="DNF","DNF",IF(V25<>"",V25/V$29*100,"")) -> 0 | X25: 0.005325463 | Y25: =IF(X25="DNF","DNF",IF(X25>0,X$29/X25*100,"")) -> 8.1087542 | Z25: 0.00071111111 | AA25: =IF(Z25="DNF","DNF",IF(Z25>0,Z$29/Z25*100,"")) -> 72.045898 | AB25: 0.0013075231 | AC25: =IF(AB25="DNF","DNF",IF(AB25>0,AB$29/AB25*100,"")) -> 33.097282 | AD25: 0.0012472222 | AE25: =IF(AD25="DNF","DNF",IF(AD25>0,AD$29/AD25*100,"")) -> 51.178545 | AF25: 0.005783912 | AG25: =IF(AF25="DNF","DNF",IF(AF25>0,AF$29/AF25*100,"")) -> 11.588258 | AH25: 0.0026152778 | AI25: =IF(AH25="DNF","DNF",IF(AH25>0,AH$29/AH25*100,"")) -> 67.16233 | AJ25: 0.00011377315 | AK25: =IF(AJ25="DNF","DNF",IF(AJ25>0,AJ$29/AJ25*100,"")) -> 62.054934 | AL25: 0.00079270833 | AM25: =IF(AL25="DNF","DNF",IF(AL25>0,AL$29/AL25*100,"")) -> 45.291283 | AO25: =A25 -> Dartmouth Alum | AP25: =SUM(C25,E25,G25,I25,K25,AI25,O25,Q25,U25,Y25,S25,,W25,AC25,AG25,AK25,AA25,AE25,M25, AM25) -> 952.70004 | AQ25: =RANK(AP25,AP25:AP28,0) -> 3 | AR25: 1 | AS25: =INDEX($AO$25:AO27,MATCH(AR3,$AQ$25:$AQ$27,0)) -> FLCC Alum | AT25: =INDEX($AP$25:$AP$27,MATCH(AS25,$AO$25:$AO$27,0)) -> 1258.6695
A26: Colby Alum | B26: 0.002521875 | C26: =IF(B26="DNF","DNF",IF(B26>0,B$29/B26*100,"")) -> 85.377943 | D26: 0.0019010417 | E26: =IF(D26="DNF","DNF",IF(D26>0,D$29/D26*100,"")) -> 92.870624 | F26: 0.002375463 | G26: =IF(F26="DNF","DNF",IF(F26>0,F$29/F26*100,"")) -> 83.482752 | H26: 0.0038791667 | I26: =IF(H26="DNF","DNF",IF(H26>0,H$29/H26*100,"")) -> 43.092851 | J26: 0.0013541667 | K26: =IF(J26="DNF","DNF",IF(J26>0,J$29/J26*100,"")) -> 60.123932 | L26: 0.0062814815 | M26: =IF(L26="DNF","DNF",IF(L26>0,L$29/L26*100,"")) -> 78.639077 | N26: 16 | O26: =IF(N26="DNF","DNF",IF(N26<>"",N26/N$29*100,"")) -> 59.259259 | P26: 0.00036400463 | Q26: =IF(P26="DNF","DNF",IF(P26>0,P$29/P26*100,"")) -> 48.203498 | R26: =Birling!B20 -> 3.21 | S26: =Birling!C20 -> 0.99016773 | U26: =IF(T26="DNF","DNF",IF(T26>0,T$29/T26*100,"")) | V26: 0 | W26: =IF(V26="DNF","DNF",IF(V26<>"",V26/V$29*100,"")) -> 0 | X26: 0.0006525463 | Y26: =IF(X26="DNF","DNF",IF(X26>0,X$29/X26*100,"")) -> 66.175949 | Z26: 0.00048159722 | AA26: =IF(Z26="DNF","DNF",IF(Z26>0,Z$29/Z26*100,"")) -> 106.38068 | AB26: 0.0010415509 | AC26: =IF(AB26="DNF","DNF",IF(AB26>0,AB$29/AB26*100,"")) -> 41.549061 | AD26: 0.0012702546 | AE26: =IF(AD26="DNF","DNF",IF(AD26>0,AD$29/AD26*100,"")) -> 50.250569 | AF26: 0.0041851852 | AG26: =IF(AF26="DNF","DNF",IF(AF26>0,AF$29/AF26*100,"")) -> 16.014934 | AH26: 0.002983912 | AI26: =IF(AH26="DNF","DNF",IF(AH26>0,AH$29/AH26*100,"")) -> 58.865056 | AJ26: 7.2569444e-05 | AK26: =IF(AJ26="DNF","DNF",IF(AJ26>0,AJ$29/AJ26*100,"")) -> 97.288676 | AL26: 0.00075347222 | AM26: =IF(AL26="DNF","DNF",IF(AL26>0,AL$29/AL26*100,"")) -> 47.64977 | AO26: =A26 -> Colby Alum | AP26: =SUM(C26,E26,G26,I26,K26,AI26,O26,Q26,U26,Y26,S26,,W26,AC26,AG26,AK26,AA26,AE26,M26, AM26) -> 1036.2148 | AQ26: =RANK(AP26,AP26:AP29,0) -> 2 | AR26: 2 | AS26: =INDEX($AO$25:AO28,MATCH(AR4,$AQ$25:$AQ$27,0)) -> Colby Alum | AT26: =INDEX($AP$25:$AP$27,MATCH(AS26,$AO$25:$AO$27,0)) -> 1036.2148
A27: FLCC Alum | B27: 0.0028851852 | C27: =IF(B27="DNF","DNF",IF(B27>0,B$29/B27*100,"")) -> 74.626926 | D27: 0.003199537 | E27: =IF(D27="DNF","DNF",IF(D27>0,D$29/D27*100,"")) -> 55.180148 | F27: 0.0025547454 | G27: =IF(F27="DNF","DNF",IF(F27>0,F$29/F27*100,"")) -> 77.624247 | H27: 0.0036909722 | I27: =IF(H27="DNF","DNF",IF(H27>0,H$29/H27*100,"")) -> 45.29006 | J27: 0.00097546296 | K27: =IF(J27="DNF","DNF",IF(J27>0,J$29/J27*100,"")) -> 83.465828 | L27: 0.0054695602 | M27: =IF(L27="DNF","DNF",IF(L27>0,L$29/L27*100,"")) -> 90.312546 | N27: 9 | O27: =IF(N27="DNF","DNF",IF(N27<>"",N27/N$29*100,"")) -> 33.333333 | P27: 0.00026215278 | Q27: =IF(P27="DNF","DNF",IF(P27>0,P$29/P27*100,"")) -> 66.931567 | R27: =Birling!B21 -> 3.53 | S27: =Birling!C21 -> 1.088876 | T27: 0.0022113426 | U27: =IF(T27="DNF","DNF",IF(T27>0,T$29/T27*100,"")) -> 37.757772 | V27: 20 | W27: =IF(V27="DNF","DNF",IF(V27<>"",V27/V$29*100,"")) -> 83.333333 | X27: 0.00078009259 | Y27: =IF(X27="DNF","DNF",IF(X27>0,X$29/X27*100,"")) -> 55.356083 | Z27: 0.00056278935 | AA27: =IF(Z27="DNF","DNF",IF(Z27>0,Z$29/Z27*100,"")) -> 91.033419 | AB27: 0.00051608796 | AC27: =IF(AB27="DNF","DNF",IF(AB27>0,AB$29/AB27*100,"")) -> 83.852882 | AD27: 0.00077013889 | AE27: =IF(AD27="DNF","DNF",IF(AD27>0,AD$29/AD27*100,"")) -> 82.882477 | AF27: 0.00076082176 | AG27: =IF(AF27="DNF","DNF",IF(AF27>0,AF$29/AF27*100,"")) -> 88.096144 | AH27: 0.0027008681 | AI27: =IF(AH27="DNF","DNF",IF(AH27>0,AH$29/AH27*100,"")) -> 65.033961 | AJ27: 0.0001025463 | AK27: =IF(AJ27="DNF","DNF",IF(AJ27>0,AJ$29/AJ27*100,"")) -> 68.848758 | AL27: 0.00048113426 | AM27: =IF(AL27="DNF","DNF",IF(AL27>0,AL$29/AL27*100,"")) -> 74.621121 | AO27: =A27 -> FLCC Alum | AP27: =SUM(C27,E27,G27,I27,K27,AI27,O27,Q27,U27,Y27,S27,,W27,AC27,AG27,AK27,AA27,AE27,M27, AM27) -> 1258.6695 | AQ27: =RANK(AP27,AP27:AP30,0) -> 1 | AR27: 3 | AS27: =INDEX($AO$25:AO29,MATCH(AR5,$AQ$25:$AQ$27,0)) -> Dartmouth Alum | AT27: =INDEX($AP$25:$AP$27,MATCH(AS27,$AO$25:$AO$27,0)) -> 952.70004
C28: =IF(B28="DNF","DNF",IF(B28>0,B$29/B28*100,"")) | E28: =IF(D28="DNF","DNF",IF(D28>0,D$29/D28*100,"")) | G28: =IF(F28="DNF","DNF",IF(F28>0,F$29/F28*100,"")) | I28: =IF(H28="DNF","DNF",IF(H28>0,H$29/H28*100,"")) | K28: =IF(J28="DNF","DNF",IF(J28>0,J$29/J28*100,"")) | M28: =IF(L28="DNF","DNF",IF(L28>0,L$29/L28*100,"")) | O28: =IF(N28="DNF","DNF",IF(N28<>"",N28/N$29*100,"")) | S28: =IF(R28="DNF","DNF",IF(R28>0,R$29/R28*100,"")) | U28: =IF(T28="DNF","DNF",IF(T28>0,T$29/T28*100,"")) | W28: =IF(V28="DNF","DNF",IF(V28<>"",V28/V$29*100,"")) | Y28: =IF(X28="DNF","DNF",IF(X28>0,X$29/X28*100,"")) | AA28: =IF(Z28="DNF","DNF",IF(Z28>0,Z$29/Z28*100,"")) | AC28: =IF(AB28="DNF","DNF",IF(AB28>0,AB$29/AB28*100,"")) | AE28: =IF(AD28="DNF","DNF",IF(AD28>0,AD$29/AD28*100,"")) | AG28: =IF(AF28="DNF","DNF",IF(AF28>0,AF$29/AF28*100,"")) | AI28: =IF(AH28="DNF","DNF",IF(AH28>0,AH$29/AH28*100,"")) | AK28: =IF(AJ28="DNF","DNF",IF(AJ28>0,AJ$29/AJ28*100,"")) | AM28: =IF(AL28="DNF","DNF",IF(AL28>0,AL$29/AL28*100,""))
A29: Top U-Grad Score | B29: =MIN(B3:B24) -> 0.002153125 | D29: =MIN(D3:D24) -> 0.0017655093 | F29: =MIN(F3:F24) -> 0.0019831019 | H29: =MIN(H3:H24) -> 0.0016716435 | J29: =MIN(J3:J17) -> 0.00081417824 | L29: =MIN(L3:L26) -> 0.0049396991 | N29: =MAX(N3:N25) -> 27 | P29: =MIN(P3:P17) -> 0.00017546296 | R29: =MAX(S3:S22) -> 100 | T29: =MIN(T3:T24) -> 0.0008349537 | V29: =MAX(V3:V22) -> 24 | X29: =MIN(X3:X24) -> 0.0004318287 | Z29: =MIN(Z3:Z17) -> 0.00051232639 | AB29: =MIN(AB3:AB24) -> 0.00043275463 | AD29: =MIN(AD3:AD24) -> 0.00063831019 | AF29: =MIN(AF3:AF25) -> 0.00067025463 | AH29: =MIN(AH3:AH24) -> 0.0017564815 | AJ29: =MIN(AJ3:AJ24) -> 7.0601852e-05 | AL29: =MIN(AL3:AL24) -> 0.00035902778
A30: 1st Place | B30: {=INDEX($A$3:$A$24, MATCH(B31,B3:B24,0))} -> FLCC | D30: {=INDEX($A$3:$A$24, MATCH(D31,D3:D24,0))} -> ESF | F30: {=INDEX($A$3:$A$24, MATCH(F31,F3:F24,0))} -> ESF | H30: {=INDEX($A$3:$A$24, MATCH(H31,H3:H24,0))} -> Paul Smiths | J30: {=INDEX($A$3:$A$24, MATCH(J31,J3:J24,0))} -> Alfred State | L30: =INDEX($A$3:$A$24, MATCH(L31,L3:L24,0)) -> Paul Smiths | N30: {=INDEX($A$3:$A$24, MATCH(N31,N3:N24,0))} -> ESF | O30: (TIE) | P30: {=INDEX($A$3:$A$24, MATCH(P31,P3:P24,0))} -> Paul Smiths | R30: {=INDEX($A$3:$A$24, MATCH(R31,S3:S24,0))} -> Paul Smiths | T30: {=INDEX($A$3:$A$24, MATCH(T31,T3:T24,0))} -> Paul Smiths | V30: {=INDEX($A$3:$A$24, MATCH(V31,V3:V24,0))} -> Alfred State | X30: {=INDEX($A$3:$A$24, MATCH(X31,X3:X24,0))} -> ESF | Z30: {=INDEX($A$3:$A$24, MATCH(Z31,Z3:Z24,0))} -> Colby | AB30: {=INDEX($A$3:$A$24, MATCH(AB31,AB3:AB24,0))} -> Alfred State | AD30: {=INDEX($A$3:$A$24, MATCH(AD31,AD3:AD24,0))} -> Paul Smiths | AF30: {=INDEX($A$3:$A$24, MATCH(AF31,AF3:AF24,0))} -> Paul Smiths | AH30: {=INDEX($A$3:$A$24, MATCH(AH31,AH3:AH24,0))} -> Ranger | AJ30: {=INDEX($A$3:$A$24, MATCH(AJ31,AJ3:AJ24,0))} -> Colby | AL30: =INDEX($A$3:$A$24, MATCH(AL31,AL3:AL24,0)) -> Unity
A31: Result | B31: =SMALL(B3:B24,1) -> 0.002153125 | D31: =SMALL(D3:D24,1) -> 0.0017655093 | F31: =SMALL(F3:F24,1) -> 0.0019831019 | H31: =SMALL(H3:H24,1) -> 0.0016716435 | J31: =SMALL(J3:J24,1) -> 0.00081417824 | L31: =SMALL(L3:L24,1) -> 0.0049396991 | N31: =LARGE(N3:N24,1) -> 27 | P31: =SMALL(P3:P24,1) -> 0.00017546296 | R31: =LARGE(S3:S24,1) -> 100 | T31: =SMALL(T3:T24,1) -> 0.0008349537 | V31: =LARGE(V3:V24,1) -> 24 | X31: =SMALL(X3:X24,1) -> 0.0004318287 | Z31: =SMALL(Z3:Z24,1) -> 0.00051232639 | AB31: =SMALL(AB3:AB24,1) -> 0.00043275463 | AD31: =SMALL(AD3:AD24,1) -> 0.00063831019 | AF31: =SMALL(AF3:AF24,1) -> 0.00067025463 | AH31: =SMALL(AH3:AH24,1) -> 0.0017564815 | AJ31: =SMALL(AJ3:AJ24,1) -> 7.0601852e-05 | AL31: =SMALL(AL3:AL24,1) -> 0.00035902778
A32: 2nd Place | B32: {=INDEX($A$3:$A$24, MATCH(B33,B3:B24,0))} -> Alfred State | D32: {=INDEX($A$3:$A$24, MATCH(D33,D3:D24,0))} -> FLCC | F32: {=INDEX($A$3:$A$24, MATCH(F33,F3:F24,0))} -> Cobleskill | H32: {=INDEX($A$3:$A$24, MATCH(H33,H3:H24,0))} -> Unity | J32: {=INDEX($A$3:$A$24, MATCH(J33,J3:J24,0))} -> ESF | L32: {=INDEX($A$3:$A$24, MATCH(L33,L3:L24,0))} -> Alfred State | N32: UNH | O32: (TIE) | P32: {=INDEX($A$3:$A$24, MATCH(P33,P3:P24,0))} -> UNH | R32: {=INDEX($A$3:$A$24, MATCH(R33,S3:S24,0))} -> ESF | T32: {=INDEX($A$3:$A$24, MATCH(T33,T3:T24,0))} -> Colby | V32: {=INDEX( $A$3:$A$24, MATCH(V33,V3:V24,0))} -> Cobleskill | W32: (TIE) | X32: {=INDEX($A$3:$A$24, MATCH(X33,X3:X24,0))} -> Paul Smiths | Z32: {=INDEX($A$3:$A$24, MATCH(Z33,Z3:Z24,0))} -> Cobleskill | AB32: {=INDEX($A$3:$A$24, MATCH(AB33,AB3:AB24,0))} -> Paul Smiths | AD32: {=INDEX($A$3:$A$24, MATCH(AD33,AD3:AD24,0))} -> Alfred State | AF32: {=INDEX($A$3:$A$24, MATCH(AF33,AF3:AF24,0))} -> ESF | AH32: {=INDEX($A$3:$A$24, MATCH(AH33,AH3:AH24,0))} -> Morrisville | AJ32: {=INDEX($A$3:$A$24, MATCH(AJ33,AJ3:AJ24,0))} -> ESF | AL32: =INDEX($A$3:$A$24, MATCH(AL33,AL3:AL24,0)) -> Paul Smiths
A33: Result | B33: =SMALL(B3:B24,2) -> 0.0022112269 | D33: =SMALL(D3:D24,2) -> 0.0017842593 | F33: =SMALL(F3:F24,2) -> 0.0020104167 | H33: =SMALL(H3:H24,2) -> 0.0019413194 | J33: =SMALL(J3:J24,2) -> 0.00082413194 | L33: =SMALL(L3:L24,2) -> 0.0053094907 | N33: =LARGE(N3:N24,2) -> 27 | P33: =SMALL(P3:P24,2) -> 0.00020277778 | R33: =LARGE(S5:S26,2) -> 90 | T33: =SMALL(T3:T24,2) -> 0.001027662 | V33: =LARGE(V3:V24,2) -> 18 | X33: =SMALL(X3:X24,2) -> 0.00046527778 | Z33: =SMALL(Z3:Z24,2) -> 0.00052899306 | AB33: =SMALL(AB3:AB24,2) -> 0.00045775463 | AD33: =SMALL(AD3:AD24,2) -> 0.0006556713 | AF33: =SMALL(AF3:AF24,2) -> 0.00076979167 | AH33: =SMALL(AH3:AH24,2) -> 0.0020053241 | AJ33: =SMALL(AJ3:AJ24,2) -> 8.1828704e-05 | AL33: =SMALL(AL3:AL24,2) -> 0.00036979167
A34: 3rd Place | B34: {=INDEX($A$3:$A$24, MATCH(B35,B3:B24,0))} -> ESF | D34: {=INDEX($A$3:$A$24, MATCH(D35,D3:D24,0))} -> Alfred State | F34: {=INDEX($A$3:$A$24, MATCH(F35,F3:F24,0))} -> FLCC | H34: {=INDEX($A$3:$A$24, MATCH(H35,H3:H24,0))} -> ESF | J34: {=INDEX($A$3:$A$24, MATCH(J35,J3:J24,0))} -> Paul Smiths | L34: {=INDEX($A$3:$A$24, MATCH(L35,L3:L24,0))} -> Ranger | N34: =INDEX( $A$3:$A$24, MATCH(N35,N3:N24,0)) -> Ranger | P34: {=INDEX($A$3:$A$24, MATCH(P35,P3:P24,0))} -> FLCC | R34: {=INDEX($A$3:$A$24, MATCH(R35,S3:S24,0))} -> UMO | T34: {=INDEX($A$3:$A$24, MATCH(T35,T3:T24,0))} -> FLCC | V34: UMO | W34: (TIE) | X34: {=INDEX($A$3:$A$24, MATCH(X35,X3:X24,0))} -> Alfred State | Z34: {=INDEX($A$3:$A$24, MATCH(Z35,Z3:Z24,0))} -> FLCC | AB34: {=INDEX($A$3:$A$24, MATCH(AB35,AB3:AB24,0))} -> Unity | AD34: {=INDEX($A$3:$A$24, MATCH(AD35,AD3:AD24,0))} -> FLCC | AF34: {=INDEX($A$3:$A$24, MATCH(AF35,AF3:AF24,0))} -> Alfred State | AH34: {=INDEX($A$3:$A$24, MATCH(AH35,AH3:AH24,0))} -> FLCC | AJ34: {=INDEX($A$3:$A$24, MATCH(AJ35,AJ3:AJ24,0))} -> Unity | AL34: =INDEX($A$3:$A$24, MATCH(AL35,AL3:AL24,0)) -> ESF
A35: Result | B35: =SMALL(B3:B24,3) -> 0.0022825231 | D35: =SMALL(D3:D24,3) -> 0.0019854167 | F35: =SMALL(F3:F24,3) -> 0.0020732639 | H35: =SMALL(H3:H24,3) -> 0.0019858796 | J35: =SMALL(J3:J24,3) -> 0.00083478009 | L35: =SMALL(L3:L24,3) -> 0.0053876157 | N35: =LARGE(N3:N24,3) -> 25 | P35: =SMALL(P3:P24,3) -> 0.00021030093 | R35: =LARGE(S7:S28,3) -> 80 | T35: =SMALL(T3:T24,3) -> 0.0010907407 | V35: =LARGE(V3:V24,3) -> 18 | X35: =SMALL(X3:X24,3) -> 0.00052916667 | Z35: =SMALL(Z3:Z24,3) -> 0.00055451389 | AB35: =SMALL(AB3:AB24,3) -> 0.00046597222 | AD35: =SMALL(AD3:AD24,3) -> 0.00071087963 | AF35: =SMALL(AF3:AF24,3) -> 0.00080555556 | AH35: =SMALL(AH3:AH24,3) -> 0.0020175926 | AJ35: =SMALL(AJ3:AJ24,3) -> 8.75e-05 | AL35: =SMALL(AL3:AL24,3) -> 0.0003943287
A60: Women's | B60: Singles Canoeing | D60: Doubles Canoeing | F60: Portage | H60: Team Pulp Throw | J60: Log Rolling | L60: Packboard Relay | N60: Axe Throw | P60: Single Buck | R60: Birling | T60: Chain Throw | V60: Disc Stack | X60: Vertical Chop | Z60: Scootloading | AB60: Crosscut Sawing | AD60: Bucksawing | AF60: Horizontal Chop | AH60: Splitting | AJ60: Pole Climb | AL60: Crosscut to Death
A61: Teams | B61: Time | C61: Score | D61: Time | E61: Score | F61: Time | G61: Score | H61: Time | I61: Score | J61: Time | K61: Score | L61: Time | M61: Score | N61: Mark | O61: Score | P61: Time | Q61: Score | R61: Time | S61: Score | T61: Time | U61: Score | V61: Raw Pts | W61: Score | X61: Time | Y61: Score | Z61: Time | AA61: Score | AB61: Time | AC61: Score | AD61: Time | AE61: Score | AF61: Time | AG61: Score | AH61: Time | AI61: Score | AJ61: Time | AK61: Score | AL61: Time | AM61: Score | AO61: TEAM | AP61: TOTAL | AQ61: RANK | AR61: Rank | AS61: Team | AT61: Score
A62: UMO | B62: 0.0042636574 | C62: =IF(B62="DNF","DNF",IF(B62>0,B$78/B62*100,"")) -> 58.955426 | D62: 0.0030770833 | E62: =IF(D62="DNF","DNF",IF(D62>0,D$78/D62*100,"")) -> 67.524261 | F62: 0.0037813657 | G62: =IF(F62="DNF","DNF",IF(F62>0,F$78/F62*100,"")) -> 68.874537 | H62: 0.0020575231 | I62: =IF(H62="DNF","DNF",IF(H62>0,H$78/H62*100,"")) -> 61.090173 | J62: 0.0014943287 | K62: =IF(J62="DNF","DNF",IF(J62>0,J$78/J62*100,"")) -> 64.212687 | L62: 0.007335706 | M62: =IF(L62="DNF","DNF",IF(L62>0,L$78/L62*100,"")) -> 85.576794 | N62: 4 | O62: =IF(N62="DNF","DNF",IF(N62<>"",N62/N$78*100,"")) -> 19.047619 | P62: 0.00025081019 | Q62: =IF(P62="DNF","DNF",IF(P62>0,P$78/P62*100,"")) -> 100 | R62: =Birling!B39 -> 7.28 | S62: =Birling!C39 -> 21.101449 | T62: 0.0013387731 | U62: =IF(T62="DNF","DNF",IF(T62>0,T$78/T62*100,"")) -> 57.23178 | V62: 5 | W62: =IF(V62="DNF","DNF",IF(V62<>"",V62/V$78*100,"")) -> 25 | X62: 0.0020559028 | Y62: =IF(X62="DNF","DNF",IF(X62>0,X$78/X62*100,"")) -> 26.144232 | Z62: 0.0028140046 | AA62: =IF(Z62="DNF","DNF",IF(Z62>0,Z$78/Z62*100,"")) -> 25.29511 | AB62: 0.00065243056 | AC62: =IF(AB62="DNF","DNF",IF(AB62>0,AB$78/AB62*100,"")) -> 100 | AD62: 0.0017790509 | AE62: =IF(AD62="DNF","DNF",IF(AD62>0,AD$78/AD62*100,"")) -> 57.432828 | AF62: 0.0068530093 | AG62: =IF(AF62="DNF","DNF",IF(AF62>0,AF$78/AF62*100,"")) -> 20.589427 | AH62: 0.0028266204 | AI62: =IF(AH62="DNF","DNF",IF(AH62>0,AH$78/AH62*100,"")) -> 65.744001 | AJ62: 0.00026990741 | AK62: =IF(AJ62="DNF","DNF",IF(AJ62>0,AJ$78/AJ62*100,"")) -> 45.540309 | AL62: 0.0017653935 | AM62: =IF(AL62="DNF","DNF",IF(AL62>0,AL$78/AL62*100,"")) -> 34.288337 | AO62: =A62 -> UMO | AP62: =SUM(C62,E62,G62,I62,K62,AI62,O62,Q62,U62,Y62,S62,,W62,AC62,AG62,AK62,AA62,AE62,M62,AM62) -> 1003.649 | AQ62: =RANK(AP62,$AP$62:$AP$73,0) -> 5 | AR62: 1 | AS62: =INDEX($AO$62:$AO$71,MATCH(AR62,$AQ$62:$AQ$71,0)) -> ESF | AT62: =INDEX($AP$62:$AP$71,MATCH(AS62,$AO$62:$AO$71,0)) -> 1696.5326
A63: FLCC | B63: 0.0026993056 | C63: =IF(B63="DNF","DNF",IF(B63>0,B$78/B63*100,"")) -> 93.122374 | D63: 0.0022332176 | E63: =IF(D63="DNF","DNF",IF(D63>0,D$78/D63*100,"")) -> 93.039648 | F63: 0.0026043981 | G63: =IF(F63="DNF","DNF",IF(F63>0,F$78/F63*100,"")) -> 100 | H63: 0.0014956019 | I63: =IF(H63="DNF","DNF",IF(H63>0,H$78/H63*100,"")) -> 84.042718 | J63: 0.0011250579 | K63: =IF(J63="DNF","DNF",IF(J63>0,J$78/J63*100,"")) -> 85.288823 | L63: 0.0079124421 | M63: =IF(L63="DNF","DNF",IF(L63>0,L$78/L63*100,"")) -> 79.339121 | N63: 12 | O63: =IF(N63="DNF","DNF",IF(N63<>"",N63/N$78*100,"")) -> 57.142857 | P63: 0.00062361111 | Q63: =IF(P63="DNF","DNF",IF(P63>0,P$78/P63*100,"")) -> 40.219005 | R63: =Birling!B40 -> 27.6 | S63: =Birling!C40 -> 80 | T63: 0.0019162037 | U63: =IF(T63="DNF","DNF",IF(T63>0,T$78/T63*100,"")) -> 39.985504 | V63: 15 | W63: =IF(V63="DNF","DNF",IF(V63<>"",V63/V$78*100,"")) -> 75 | X63: 0.0016094907 | Y63: =IF(X63="DNF","DNF",IF(X63>0,X$78/X63*100,"")) -> 33.395657 | Z63: 0.0013181713 | AA63: =IF(Z63="DNF","DNF",IF(Z63>0,Z$78/Z63*100,"")) -> 53.999473 | AB63: 0.00080648148 | AC63: =IF(AB63="DNF","DNF",IF(AB63>0,AB$78/AB63*100,"")) -> 80.898393 | AD63: 0.001043287 | AE63: =IF(AD63="DNF","DNF",IF(AD63>0,AD$78/AD63*100,"")) -> 97.936543 | AF63: 0.0052701389 | AG63: =IF(AF63="DNF","DNF",IF(AF63>0,AF$78/AF63*100,"")) -> 26.7734 | AH63: 0.0025527778 | AI63: =IF(AH63="DNF","DNF",IF(AH63>0,AH$78/AH63*100,"")) -> 72.796518 | AJ63: 0.00012615741 | AK63: =IF(AJ63="DNF","DNF",IF(AJ63>0,AJ$78/AJ63*100,"")) -> 97.431193 | AL63: 0.00083888889 | AM63: =IF(AL63="DNF","DNF",IF(AL63>0,AL$78/AL63*100,"")) -> 72.157837 | AO63: =A63 -> FLCC | AP63: =SUM(C63,E63,G63,I63,K63,AI63,O63,Q63,U63,Y63,S63,,W63,AC63,AG63,AK63,AA63,AE63,M63,AM63) -> 1362.5691 | AQ63: =RANK(AP63,$AP$62:$AP$73,0) -> 3 | AR63: 2 | AS63: =INDEX($AO$62:$AO$71,MATCH(AR63,$AQ$62:$AQ$71,0)) -> Colby | AT63: =INDEX($AP$62:$AP$71,MATCH(AS63,$AO$62:$AO$71,0)) -> 1490.6866
A64: Colby | B64: 0.0026087963 | C64: =IF(B64="DNF","DNF",IF(B64>0,B$78/B64*100,"")) -> 96.35315 | D64: 0.0022613426 | E64: =IF(D64="DNF","DNF",IF(D64>0,D$78/D64*100,"")) -> 91.882485 | F64: 0.003222338 | G64: =IF(F64="DNF","DNF",IF(F64>0,F$78/F64*100,"")) -> 80.823246 | H64: 0.0013466435 | I64: =IF(H64="DNF","DNF",IF(H64>0,H$78/H64*100,"")) -> 93.339063 | J64: 0.0012730324 | K64: =IF(J64="DNF","DNF",IF(J64>0,J$78/J64*100,"")) -> 75.375034 | L64: 0.0073517361 | M64: =IF(L64="DNF","DNF",IF(L64>0,L$78/L64*100,"")) -> 85.390198 | N64: 17 | O64: =IF(N64="DNF","DNF",IF(N64<>"",N64/N$78*100,"")) -> 80.952381 | P64: 0.0003 | Q64: =IF(P64="DNF","DNF",IF(P64>0,P$78/P64*100,"")) -> 83.603395 | R64: =Birling!B41 -> 188.4 | S64: =Birling!C41 -> 90 | T64: 0.0007662037 | U64: =IF(T64="DNF","DNF",IF(T64>0,T$78/T64*100,"")) -> 100 | V64: 2 | W64: =IF(V64="DNF","DNF",IF(V64<>"",V64/V$78*100,"")) -> 10 | X64: 0.0011185185 | Y64: =IF(X64="DNF","DNF",IF(X64>0,X$78/X64*100,"")) -> 48.054636 | Z64: 0.00071180556 | AA64: =IF(Z64="DNF","DNF",IF(Z64>0,Z$78/Z64*100,"")) -> 100 | AB64: 0.00099606481 | AC64: =IF(AB64="DNF","DNF",IF(AB64>0,AB$78/AB64*100,"")) -> 65.500813 | AD64: 0.0012606481 | AE64: =IF(AD64="DNF","DNF",IF(AD64>0,AD$78/AD64*100,"")) -> 81.050312 | AF64: 0.0020136574 | AG64: =IF(AF64="DNF","DNF",IF(AF64>0,AF$78/AF64*100,"")) -> 70.071273 | AH64: 0.0018583333 | AI64: =IF(AH64="DNF","DNF",IF(AH64>0,AH$78/AH64*100,"")) -> 100 | AJ64: 0.00013854167 | AK64: =IF(AJ64="DNF","DNF",IF(AJ64>0,AJ$78/AJ64*100,"")) -> 88.721805 | AL64: 0.0012211806 | AM64: =IF(AL64="DNF","DNF",IF(AL64>0,AL$78/AL64*100,"")) -> 49.568761 | AO64: =A64 -> Colby | AP64: =SUM(C64,E64,G64,I64,K64,AI64,O64,Q64,U64,Y64,S64,,W64,AC64,AG64,AK64,AA64,AE64,M64,AM64) -> 1490.6866 | AQ64: =RANK(AP64,$AP$62:$AP$73,0) -> 2 | AR64: 3 | AS64: =INDEX($AO$62:$AO$71,MATCH(AR64,$AQ$62:$AQ$71,0)) -> FLCC | AT64: =INDEX($AP$62:$AP$71,MATCH(AS64,$AO$62:$AO$71,0)) -> 1362.5691
A65: Unity | B65: 0.0035505787 | C65: =IF(B65="DNF","DNF",IF(B65>0,B$78/B65*100,"")) -> 70.79571 | D65: 0.003596412 | E65: =IF(D65="DNF","DNF",IF(D65>0,D$78/D65*100,"")) -> 57.77363 | F65: 0.0031268519 | G65: =IF(F65="DNF","DNF",IF(F65>0,F$78/F65*100,"")) -> 83.291383 | H65: 0.0019125 | I65: =IF(H65="DNF","DNF",IF(H65>0,H$78/H65*100,"")) -> 65.722585 | J65: 0.0012859954 | K65: =IF(J65="DNF","DNF",IF(J65>0,J$78/J65*100,"")) -> 74.615246 | L65: 0.0080470486 | M65: =IF(L65="DNF","DNF",IF(L65>0,L$78/L65*100,"")) -> 78.011981 | N65: 8 | O65: =IF(N65="DNF","DNF",IF(N65<>"",N65/N$78*100,"")) -> 38.095238 | P65: 0.00045150463 | Q65: =IF(P65="DNF","DNF",IF(P65>0,P$78/P65*100,"")) -> 55.549859 | R65: =Birling!B42 -> 2.9 | S65: =Birling!C42 -> 8.4057971 | T65: 0.0017400463 | U65: =IF(T65="DNF","DNF",IF(T65>0,T$78/T65*100,"")) -> 44.033524 | V65: 7 | W65: =IF(V65="DNF","DNF",IF(V65<>"",V65/V$78*100,"")) -> 35 | X65: 0.0053251157 | Y65: =IF(X65="DNF","DNF",IF(X65>0,X$78/X65*100,"")) -> 10.093677 | Z65: 0.0016336806 | AA65: =IF(Z65="DNF","DNF",IF(Z65>0,Z$78/Z65*100,"")) -> 43.57067 | AB65: 0.00095081019 | AC65: =IF(AB65="DNF","DNF",IF(AB65>0,AB$78/AB65*100,"")) -> 68.618381 | AD65: 0.0015702546 | AE65: =IF(AD65="DNF","DNF",IF(AD65>0,AD$78/AD65*100,"")) -> 65.069654 | AF65: 0.0046166667 | AG65: =IF(AF65="DNF","DNF",IF(AF65>0,AF$78/AF65*100,"")) -> 30.563077 | AH65: 0.0021430556 | AI65: =IF(AH65="DNF","DNF",IF(AH65>0,AH$78/AH65*100,"")) -> 86.714193 | AJ65: 0.00079930556 | AK65: =IF(AJ65="DNF","DNF",IF(AJ65>0,AJ$78/AJ65*100,"")) -> 15.377932 | AL65: 0.00088043981 | AM65: =IF(AL65="DNF","DNF",IF(AL65>0,AL$78/AL65*100,"")) -> 68.752465 | AO65: =A65 -> Unity | AP65: =SUM(C65,E65,G65,I65,K65,AI65,O65,Q65,U65,Y65,S65,,W65,AC65,AG65,AK65,AA65,AE65,M65,AM65) -> 1000.055 | AQ65: =RANK(AP65,$AP$62:$AP$73,0) -> 6 | AR65: 4 | AS65: =INDEX($AO$62:$AO$71,MATCH(AR65,$AQ$62:$AQ$71,0)) -> UNH | AT65: =INDEX($AP$62:$AP$71,MATCH(AS65,$AO$62:$AO$71,0)) -> 1305.4951
A66: ESF | B66: 0.0025136574 | C66: =IF(B66="DNF","DNF",IF(B66>0,B$78/B66*100,"")) -> 100 | D66: 0.0020777778 | E66: =IF(D66="DNF","DNF",IF(D66>0,D$78/D66*100,"")) -> 100 | F66: 0.0028041667 | G66: =IF(F66="DNF","DNF",IF(F66>0,F$78/F66*100,"")) -> 92.876011 | H66: 0.0012569444 | I66: =IF(H66="DNF","DNF",IF(H66>0,H$78/H66*100,"")) -> 100 | J66: 0.00095954861 | K66: =IF(J66="DNF","DNF",IF(J66>0,J$78/J66*100,"")) -> 100 | L66: 0.006277662 | M66: =IF(L66="DNF","DNF",IF(L66>0,L$78/L66*100,"")) -> 100 | N66: 13 | O66: =IF(N66="DNF","DNF",IF(N66<>"",N66/N$78*100,"")) -> 61.904762 | P66: 0.00035324074 | Q66: =IF(P66="DNF","DNF",IF(P66>0,P$78/P66*100,"")) -> 71.002621 | R66: =Birling!B43 -> 300 | S66: =Birling!C43 -> 100 | T66: 0.0015266204 | U66: =IF(T66="DNF","DNF",IF(T66>0,T$78/T66*100,"")) -> 50.189538 | V66: 20 | W66: =IF(V66="DNF","DNF",IF(V66<>"",V66/V$78*100,"")) -> 100 | X66: 0.0005375 | Y66: =IF(X66="DNF","DNF",IF(X66>0,X$78/X66*100,"")) -> 100 | Z66: 0.0010018519 | AA66: =IF(Z66="DNF","DNF",IF(Z66>0,Z$78/Z66*100,"")) -> 71.048983 | AB66: 0.00065243056 | AC66: =IF(AB66="DNF","DNF",IF(AB66>0,AB$78/AB66*100,"")) -> 100 | AD66: 0.0010217593 | AE66: =IF(AD66="DNF","DNF",IF(AD66>0,AD$78/AD66*100,"")) -> 100 | AF66: 0.0014109954 | AG66: =IF(AF66="DNF","DNF",IF(AF66>0,AF$78/AF66*100,"")) -> 100 | AH66: 0.0022431713 | AI66: =IF(AH66="DNF","DNF",IF(AH66>0,AH$78/AH66*100,"")) -> 82.844022 | AJ66: 0.000184375 | AK66: =IF(AJ66="DNF","DNF",IF(AJ66>0,AJ$78/AJ66*100,"")) -> 66.666667 | AL66: 0.00060532407 | AM66: =IF(AL66="DNF","DNF",IF(AL66>0,AL$78/AL66*100,"")) -> 100 | AO66: =A66 -> ESF | AP66: =SUM(C66,E66,G66,I66,K66,AI66,O66,Q66,U66,Y66,S66,,W66,AC66,AG66,AK66,AA66,AE66,M66,AM66) -> 1696.5326 | AQ66: =RANK(AP66,$AP$62:$AP$73,0) -> 1 | AR66: 5 | AS66: =INDEX($AO$62:$AO$71,MATCH(AR66,$AQ$62:$AQ$71,0)) -> UMO | AT66: =INDEX($AP$62:$AP$71,MATCH(AS66,$AO$62:$AO$71,0)) -> 1003.649
...

Sheet Birling
A1: Men's | B1: Best time | C1: Score from final
A2: Teams
A3: FLCC | B3: 54.31 | C3: =B3/$B$15*80 -> 16.752651
A4: Alfred State | B4: 42.6 | C4: =B4/$B$15*80 -> 13.140544
A5: ESF | B5: 113.57 | C5: 90
A6: Morrisville | B6: 3 | C6: =B6/$B$15*80 -> 0.9253904
A7: UNH | B7: 137.41 | C7: 85
A8: Unity | B8: 18.28 | C8: =B8/$B$15*80 -> 5.6387122
A9: UVM | B9: 6.81 | C9: =B9/$B$15*80 -> 2.1006362
A10: Cobleskill | B10: 3.03 | C10: =B10/$B$15*80 -> 0.9346443
A11: Dartmouth | B11: 14.12 | C11: =B11/$B$15*80 -> 4.3555041
A12: Ranger | B12: 4.81 | C12: =B12/$B$15*80 -> 1.4837093
A13: Paul Smiths | B13: 173.05 | C13: 100
A14: Colby | B14: 16.72 | C14: =B14/$B$15*80 -> 5.1575092
A15: UMO | B15: 259.35 | C15: 80
A19: Dartmouth Alum | B19: 20.69 | C19: =B19/$B$15*80 -> 6.3821091
A20: Colby Alum | B20: 3.21 | C20: =B20/$B$15*80 -> 0.99016773
A21: FLCC Alum | B21: 3.53 | C21: =B21/$B$15*80 -> 1.088876
B28: Average | C28: Score from final
A29: Top U-Grad Score
A30: 1st Place
A31: Result
A32: 2nd Place
A33: Result
A34: 3rd Place
A35: Result
A37: Women's
A38: Teams
A39: UMO | B39: 7.28 | C39: =B39/$B$40*80 -> 21.101449
A40: Finger Lakes | B40: 27.6 | C40: 80
A41: Colby | B41: 188.4 | C41: 90
A42: Unity | B42: 2.9 | C42: =B42/$B$40*80 -> 8.4057971
A43: ESF | B43: 300 | C43: 100
A44: UNH | B44: 300 | C44: 85
B54: Average | C54: Score from final
A55: Top U-grad Score
A56: 1st Place
A57: Result
A58: 2nd Place
A59: Result
...
